[2022-06-28 15:09:46,311] {taskinstance.py:1159} INFO - Dependencies all met for <TaskInstance: process-food-waste-data.trigger manual__2022-06-28T15:09:16.888051+00:00 [queued]>
[2022-06-28 15:09:46,322] {taskinstance.py:1159} INFO - Dependencies all met for <TaskInstance: process-food-waste-data.trigger manual__2022-06-28T15:09:16.888051+00:00 [queued]>
[2022-06-28 15:09:46,322] {taskinstance.py:1356} INFO - 
--------------------------------------------------------------------------------
[2022-06-28 15:09:46,322] {taskinstance.py:1357} INFO - Starting attempt 1 of 2
[2022-06-28 15:09:46,322] {taskinstance.py:1358} INFO - 
--------------------------------------------------------------------------------
[2022-06-28 15:09:46,336] {taskinstance.py:1377} INFO - Executing <Task(TriggerDagRunOperator): trigger> on 2022-06-28 15:09:16.888051+00:00
[2022-06-28 15:09:46,343] {clientserver.py:543} INFO - Closing down clientserver connection
[2022-06-28 15:09:46,342] {standard_task_runner.py:52} INFO - Started process 1036 to run task
[2022-06-28 15:09:46,346] {standard_task_runner.py:79} INFO - Running: ['***', 'tasks', 'run', 'process-food-waste-data', 'trigger', 'manual__2022-06-28T15:09:16.888051+00:00', '--job-id', '535', '--raw', '--subdir', 'DAGS_FOLDER/02_data_process_dag.py', '--cfg-path', '/tmp/tmpqs7x0ykq', '--error-file', '/tmp/tmpl8vqjwpd']
[2022-06-28 15:09:46,347] {standard_task_runner.py:80} INFO - Job 535: Subtask trigger
[2022-06-28 15:09:46,400] {task_command.py:370} INFO - Running <TaskInstance: process-food-waste-data.trigger manual__2022-06-28T15:09:16.888051+00:00 [running]> on host 375d46b24910
[2022-06-28 15:09:46,502] {taskinstance.py:1571} INFO - Exporting the following env vars:
AIRFLOW_CTX_DAG_OWNER=***
AIRFLOW_CTX_DAG_ID=process-food-waste-data
AIRFLOW_CTX_TASK_ID=trigger
AIRFLOW_CTX_EXECUTION_DATE=2022-06-28T15:09:16.888051+00:00
AIRFLOW_CTX_TRY_NUMBER=1
AIRFLOW_CTX_DAG_RUN_ID=manual__2022-06-28T15:09:16.888051+00:00
[2022-06-28 15:09:46,809] {clientserver.py:505} INFO - Error while sending or receiving.
Traceback (most recent call last):
  File "/home/airflow/.local/lib/python3.7/site-packages/py4j/clientserver.py", line 503, in send_command
    self.socket.sendall(command.encode("utf-8"))
ConnectionResetError: [Errno 104] Connection reset by peer
[2022-06-28 15:09:46,810] {clientserver.py:543} INFO - Closing down clientserver connection
[2022-06-28 15:09:46,810] {java_gateway.py:1052} INFO - Exception while sending command.
Traceback (most recent call last):
  File "/home/airflow/.local/lib/python3.7/site-packages/py4j/clientserver.py", line 503, in send_command
    self.socket.sendall(command.encode("utf-8"))
ConnectionResetError: [Errno 104] Connection reset by peer

During handling of the above exception, another exception occurred:

Traceback (most recent call last):
  File "/home/airflow/.local/lib/python3.7/site-packages/py4j/java_gateway.py", line 1038, in send_command
    response = connection.send_command(command)
  File "/home/airflow/.local/lib/python3.7/site-packages/py4j/clientserver.py", line 507, in send_command
    "Error while sending", e, proto.ERROR_ON_SEND)
py4j.protocol.Py4JNetworkError: Error while sending
[2022-06-28 15:09:46,813] {clientserver.py:543} INFO - Closing down clientserver connection
[2022-06-28 15:09:47,465] {trigger_dagrun.py:181} INFO - Waiting for data_to_dw_bq on 2022-06-28T15:09:46.503482+00:00 to become allowed state ['success'] ...
[2022-06-28 15:10:47,530] {trigger_dagrun.py:181} INFO - Waiting for data_to_dw_bq on 2022-06-28T15:09:46.503482+00:00 to become allowed state ['success'] ...
[2022-06-28 15:11:47,599] {trigger_dagrun.py:181} INFO - Waiting for data_to_dw_bq on 2022-06-28T15:09:46.503482+00:00 to become allowed state ['success'] ...
[2022-06-28 15:12:47,663] {trigger_dagrun.py:181} INFO - Waiting for data_to_dw_bq on 2022-06-28T15:09:46.503482+00:00 to become allowed state ['success'] ...
[2022-06-28 15:13:47,725] {trigger_dagrun.py:181} INFO - Waiting for data_to_dw_bq on 2022-06-28T15:09:46.503482+00:00 to become allowed state ['success'] ...
[2022-06-28 15:13:49,087] {local_task_job.py:221} WARNING - State of this instance has been externally set to failed. Terminating instance.
[2022-06-28 15:13:49,088] {process_utils.py:129} INFO - Sending Signals.SIGTERM to group 1036. PIDs of all processes in the group: [1036]
[2022-06-28 15:13:49,088] {process_utils.py:80} INFO - Sending the signal Signals.SIGTERM to group 1036
[2022-06-28 15:13:49,088] {taskinstance.py:1541} ERROR - Received SIGTERM. Terminating subprocesses.
[2022-06-28 15:13:49,114] {process_utils.py:75} INFO - Process psutil.Process(pid=1036, status='terminated', exitcode=0, started='15:09:45') (1036) terminated with exit code 0
