[2022-06-21 16:28:32,764] {taskinstance.py:1159} INFO - Dependencies all met for <TaskInstance: data_ingestion_gcs_dag.download_dataset_task manual__2022-06-21T16:28:32.075206+00:00 [queued]>
[2022-06-21 16:28:32,769] {taskinstance.py:1159} INFO - Dependencies all met for <TaskInstance: data_ingestion_gcs_dag.download_dataset_task manual__2022-06-21T16:28:32.075206+00:00 [queued]>
[2022-06-21 16:28:32,769] {taskinstance.py:1356} INFO - 
--------------------------------------------------------------------------------
[2022-06-21 16:28:32,769] {taskinstance.py:1357} INFO - Starting attempt 1 of 2
[2022-06-21 16:28:32,769] {taskinstance.py:1358} INFO - 
--------------------------------------------------------------------------------
[2022-06-21 16:28:32,780] {taskinstance.py:1377} INFO - Executing <Task(PythonOperator): download_dataset_task> on 2022-06-21 16:28:32.075206+00:00
[2022-06-21 16:28:32,787] {standard_task_runner.py:52} INFO - Started process 271 to run task
[2022-06-21 16:28:32,789] {standard_task_runner.py:79} INFO - Running: ['***', 'tasks', 'run', 'data_ingestion_gcs_dag', 'download_dataset_task', 'manual__2022-06-21T16:28:32.075206+00:00', '--job-id', '37', '--raw', '--subdir', 'DAGS_FOLDER/dags.py', '--cfg-path', '/tmp/tmpp8dg8dpt', '--error-file', '/tmp/tmpi0xy5ow_']
[2022-06-21 16:28:32,789] {standard_task_runner.py:80} INFO - Job 37: Subtask download_dataset_task
[2022-06-21 16:28:32,825] {task_command.py:370} INFO - Running <TaskInstance: data_ingestion_gcs_dag.download_dataset_task manual__2022-06-21T16:28:32.075206+00:00 [running]> on host 89ce8768abec
[2022-06-21 16:28:32,875] {taskinstance.py:1571} INFO - Exporting the following env vars:
AIRFLOW_CTX_DAG_OWNER=***
AIRFLOW_CTX_DAG_ID=data_ingestion_gcs_dag
AIRFLOW_CTX_TASK_ID=download_dataset_task
AIRFLOW_CTX_EXECUTION_DATE=2022-06-21T16:28:32.075206+00:00
AIRFLOW_CTX_TRY_NUMBER=1
AIRFLOW_CTX_DAG_RUN_ID=manual__2022-06-21T16:28:32.075206+00:00
[2022-06-21 16:28:32,884] {taskinstance.py:1889} ERROR - Task failed with exception
Traceback (most recent call last):
  File "/home/airflow/.local/lib/python3.7/site-packages/airflow/operators/python.py", line 171, in execute
    return_value = self.execute_callable()
  File "/home/airflow/.local/lib/python3.7/site-packages/airflow/operators/python.py", line 189, in execute_callable
    return self.python_callable(*self.op_args, **self.op_kwargs)
  File "/opt/airflow/dags/dags.py", line 72, in download_data
    from kaggle.api.kaggle_api_extended import KaggleApi
  File "/home/airflow/.local/lib/python3.7/site-packages/kaggle/__init__.py", line 23, in <module>
    api.authenticate()
  File "/home/airflow/.local/lib/python3.7/site-packages/kaggle/api/kaggle_api_extended.py", line 166, in authenticate
    self.config_file, self.config_dir))
OSError: Could not find kaggle.json. Make sure it's located in /home/***/.kaggle. Or use the environment method.
[2022-06-21 16:28:32,890] {taskinstance.py:1400} INFO - Marking task as UP_FOR_RETRY. dag_id=data_ingestion_gcs_dag, task_id=download_dataset_task, execution_date=20220621T162832, start_date=20220621T162832, end_date=20220621T162832
[2022-06-21 16:28:32,898] {standard_task_runner.py:97} ERROR - Failed to execute job 37 for task download_dataset_task (Could not find kaggle.json. Make sure it's located in /home/***/.kaggle. Or use the environment method.; 271)
[2022-06-21 16:28:32,921] {local_task_job.py:156} INFO - Task exited with return code 1
[2022-06-21 16:28:32,962] {local_task_job.py:273} INFO - 0 downstream tasks scheduled from follow-on schedule check
