[2022-06-28 15:09:22,569] {taskinstance.py:1159} INFO - Dependencies all met for <TaskInstance: process-food-waste-data.process_data_task manual__2022-06-28T15:09:16.888051+00:00 [queued]>
[2022-06-28 15:09:22,577] {taskinstance.py:1159} INFO - Dependencies all met for <TaskInstance: process-food-waste-data.process_data_task manual__2022-06-28T15:09:16.888051+00:00 [queued]>
[2022-06-28 15:09:22,577] {taskinstance.py:1356} INFO - 
--------------------------------------------------------------------------------
[2022-06-28 15:09:22,577] {taskinstance.py:1357} INFO - Starting attempt 1 of 2
[2022-06-28 15:09:22,577] {taskinstance.py:1358} INFO - 
--------------------------------------------------------------------------------
[2022-06-28 15:09:22,590] {taskinstance.py:1377} INFO - Executing <Task(PythonOperator): process_data_task> on 2022-06-28 15:09:16.888051+00:00
[2022-06-28 15:09:22,596] {clientserver.py:543} INFO - Closing down clientserver connection
[2022-06-28 15:09:22,596] {standard_task_runner.py:52} INFO - Started process 778 to run task
[2022-06-28 15:09:22,599] {standard_task_runner.py:79} INFO - Running: ['***', 'tasks', 'run', 'process-food-waste-data', 'process_data_task', 'manual__2022-06-28T15:09:16.888051+00:00', '--job-id', '534', '--raw', '--subdir', 'DAGS_FOLDER/02_data_process_dag.py', '--cfg-path', '/tmp/tmpin1znl_g', '--error-file', '/tmp/tmpqq0tf2dk']
[2022-06-28 15:09:22,600] {standard_task_runner.py:80} INFO - Job 534: Subtask process_data_task
[2022-06-28 15:09:22,639] {task_command.py:370} INFO - Running <TaskInstance: process-food-waste-data.process_data_task manual__2022-06-28T15:09:16.888051+00:00 [running]> on host 375d46b24910
[2022-06-28 15:09:22,696] {taskinstance.py:1571} INFO - Exporting the following env vars:
AIRFLOW_CTX_DAG_OWNER=***
AIRFLOW_CTX_DAG_ID=process-food-waste-data
AIRFLOW_CTX_TASK_ID=process_data_task
AIRFLOW_CTX_EXECUTION_DATE=2022-06-28T15:09:16.888051+00:00
AIRFLOW_CTX_TRY_NUMBER=1
AIRFLOW_CTX_DAG_RUN_ID=manual__2022-06-28T15:09:16.888051+00:00
[2022-06-28 15:09:23,056] {clientserver.py:505} INFO - Error while sending or receiving.
Traceback (most recent call last):
  File "/home/airflow/.local/lib/python3.7/site-packages/py4j/clientserver.py", line 503, in send_command
    self.socket.sendall(command.encode("utf-8"))
ConnectionResetError: [Errno 104] Connection reset by peer
[2022-06-28 15:09:23,057] {clientserver.py:543} INFO - Closing down clientserver connection
[2022-06-28 15:09:23,057] {java_gateway.py:1052} INFO - Exception while sending command.
Traceback (most recent call last):
  File "/home/airflow/.local/lib/python3.7/site-packages/py4j/clientserver.py", line 503, in send_command
    self.socket.sendall(command.encode("utf-8"))
ConnectionResetError: [Errno 104] Connection reset by peer

During handling of the above exception, another exception occurred:

Traceback (most recent call last):
  File "/home/airflow/.local/lib/python3.7/site-packages/py4j/java_gateway.py", line 1038, in send_command
    response = connection.send_command(command)
  File "/home/airflow/.local/lib/python3.7/site-packages/py4j/clientserver.py", line 507, in send_command
    "Error while sending", e, proto.ERROR_ON_SEND)
py4j.protocol.Py4JNetworkError: Error while sending
[2022-06-28 15:09:23,060] {clientserver.py:543} INFO - Closing down clientserver connection
[2022-06-28 15:09:29,852] {logging_mixin.py:115} INFO - 171  nÂº records
[2022-06-28 15:09:31,836] {logging_mixin.py:115} INFO - There were  8  records eliminated by ensuring date format.
[2022-06-28 15:09:38,990] {python.py:173} INFO - Done. Returned value was: None
[2022-06-28 15:09:39,110] {taskinstance.py:1400} INFO - Marking task as SUCCESS. dag_id=process-food-waste-data, task_id=process_data_task, execution_date=20220628T150916, start_date=20220628T150922, end_date=20220628T150939
[2022-06-28 15:09:39,148] {local_task_job.py:156} INFO - Task exited with return code 0
[2022-06-28 15:09:39,169] {local_task_job.py:273} INFO - 1 downstream tasks scheduled from follow-on schedule check
