[2022-06-21 16:09:23,889] {taskinstance.py:1159} INFO - Dependencies all met for <TaskInstance: data_ingestion_gcs_dag.download_dataset_task manual__2022-06-21T16:09:21.702680+00:00 [queued]>
[2022-06-21 16:09:23,895] {taskinstance.py:1159} INFO - Dependencies all met for <TaskInstance: data_ingestion_gcs_dag.download_dataset_task manual__2022-06-21T16:09:21.702680+00:00 [queued]>
[2022-06-21 16:09:23,895] {taskinstance.py:1356} INFO - 
--------------------------------------------------------------------------------
[2022-06-21 16:09:23,895] {taskinstance.py:1357} INFO - Starting attempt 1 of 2
[2022-06-21 16:09:23,895] {taskinstance.py:1358} INFO - 
--------------------------------------------------------------------------------
[2022-06-21 16:09:23,906] {taskinstance.py:1377} INFO - Executing <Task(PythonOperator): download_dataset_task> on 2022-06-21 16:09:21.702680+00:00
[2022-06-21 16:09:23,913] {standard_task_runner.py:52} INFO - Started process 93 to run task
[2022-06-21 16:09:23,915] {standard_task_runner.py:79} INFO - Running: ['***', 'tasks', 'run', 'data_ingestion_gcs_dag', 'download_dataset_task', 'manual__2022-06-21T16:09:21.702680+00:00', '--job-id', '23', '--raw', '--subdir', 'DAGS_FOLDER/dags.py', '--cfg-path', '/tmp/tmpstzr4dzr', '--error-file', '/tmp/tmp9hxunkyq']
[2022-06-21 16:09:23,916] {standard_task_runner.py:80} INFO - Job 23: Subtask download_dataset_task
[2022-06-21 16:09:23,952] {task_command.py:370} INFO - Running <TaskInstance: data_ingestion_gcs_dag.download_dataset_task manual__2022-06-21T16:09:21.702680+00:00 [running]> on host be2e415cb0fb
[2022-06-21 16:09:24,008] {taskinstance.py:1571} INFO - Exporting the following env vars:
AIRFLOW_CTX_DAG_OWNER=***
AIRFLOW_CTX_DAG_ID=data_ingestion_gcs_dag
AIRFLOW_CTX_TASK_ID=download_dataset_task
AIRFLOW_CTX_EXECUTION_DATE=2022-06-21T16:09:21.702680+00:00
AIRFLOW_CTX_TRY_NUMBER=1
AIRFLOW_CTX_DAG_RUN_ID=manual__2022-06-21T16:09:21.702680+00:00
[2022-06-21 16:09:24,008] {logging_mixin.py:115} INFO - #############################
[2022-06-21 16:09:24,009] {logging_mixin.py:115} INFO - /opt/***
[2022-06-21 16:09:24,009] {taskinstance.py:1889} ERROR - Task failed with exception
Traceback (most recent call last):
  File "/home/airflow/.local/lib/python3.7/site-packages/airflow/operators/python.py", line 171, in execute
    return_value = self.execute_callable()
  File "/home/airflow/.local/lib/python3.7/site-packages/airflow/operators/python.py", line 189, in execute_callable
    return self.python_callable(*self.op_args, **self.op_kwargs)
  File "/opt/airflow/dags/dags.py", line 32, in download_data
    print(filename)
UnboundLocalError: local variable 'filename' referenced before assignment
[2022-06-21 16:09:24,014] {taskinstance.py:1400} INFO - Marking task as UP_FOR_RETRY. dag_id=data_ingestion_gcs_dag, task_id=download_dataset_task, execution_date=20220621T160921, start_date=20220621T160923, end_date=20220621T160924
[2022-06-21 16:09:24,024] {standard_task_runner.py:97} ERROR - Failed to execute job 23 for task download_dataset_task (local variable 'filename' referenced before assignment; 93)
[2022-06-21 16:09:24,047] {local_task_job.py:156} INFO - Task exited with return code 1
[2022-06-21 16:09:24,075] {local_task_job.py:273} INFO - 0 downstream tasks scheduled from follow-on schedule check
