[2022-06-21 16:20:34,249] {taskinstance.py:1159} INFO - Dependencies all met for <TaskInstance: data_ingestion_gcs_dag.format_to_parquet_task manual__2022-06-21T16:20:27.437267+00:00 [queued]>
[2022-06-21 16:20:34,276] {taskinstance.py:1159} INFO - Dependencies all met for <TaskInstance: data_ingestion_gcs_dag.format_to_parquet_task manual__2022-06-21T16:20:27.437267+00:00 [queued]>
[2022-06-21 16:20:34,276] {taskinstance.py:1356} INFO - 
--------------------------------------------------------------------------------
[2022-06-21 16:20:34,277] {taskinstance.py:1357} INFO - Starting attempt 1 of 2
[2022-06-21 16:20:34,277] {taskinstance.py:1358} INFO - 
--------------------------------------------------------------------------------
[2022-06-21 16:20:34,325] {taskinstance.py:1377} INFO - Executing <Task(PythonOperator): format_to_parquet_task> on 2022-06-21 16:20:27.437267+00:00
[2022-06-21 16:20:34,336] {standard_task_runner.py:52} INFO - Started process 100 to run task
[2022-06-21 16:20:34,342] {standard_task_runner.py:79} INFO - Running: ['***', 'tasks', 'run', 'data_ingestion_gcs_dag', 'format_to_parquet_task', 'manual__2022-06-21T16:20:27.437267+00:00', '--job-id', '32', '--raw', '--subdir', 'DAGS_FOLDER/dags.py', '--cfg-path', '/tmp/tmpze0urc92', '--error-file', '/tmp/tmpwju2xe0f']
[2022-06-21 16:20:34,349] {standard_task_runner.py:80} INFO - Job 32: Subtask format_to_parquet_task
[2022-06-21 16:20:34,459] {task_command.py:370} INFO - Running <TaskInstance: data_ingestion_gcs_dag.format_to_parquet_task manual__2022-06-21T16:20:27.437267+00:00 [running]> on host 15e20bae5eef
[2022-06-21 16:20:34,612] {taskinstance.py:1571} INFO - Exporting the following env vars:
AIRFLOW_CTX_DAG_OWNER=***
AIRFLOW_CTX_DAG_ID=data_ingestion_gcs_dag
AIRFLOW_CTX_TASK_ID=format_to_parquet_task
AIRFLOW_CTX_EXECUTION_DATE=2022-06-21T16:20:27.437267+00:00
AIRFLOW_CTX_TRY_NUMBER=1
AIRFLOW_CTX_DAG_RUN_ID=manual__2022-06-21T16:20:27.437267+00:00
[2022-06-21 16:20:34,615] {taskinstance.py:1889} ERROR - Task failed with exception
Traceback (most recent call last):
  File "/home/airflow/.local/lib/python3.7/site-packages/airflow/operators/python.py", line 171, in execute
    return_value = self.execute_callable()
  File "/home/airflow/.local/lib/python3.7/site-packages/airflow/operators/python.py", line 189, in execute_callable
    return self.python_callable(*self.op_args, **self.op_kwargs)
  File "/opt/airflow/dags/dags.py", line 80, in format_to_parquet
    table = pv.read_csv(src_file)
  File "pyarrow/_csv.pyx", line 881, in pyarrow._csv.read_csv
  File "pyarrow/_csv.pyx", line 774, in pyarrow._csv._get_reader
  File "pyarrow/io.pxi", line 1631, in pyarrow.lib.get_input_stream
  File "pyarrow/io.pxi", line 1602, in pyarrow.lib.get_native_file
  File "pyarrow/io.pxi", line 896, in pyarrow.lib.OSFile.__cinit__
  File "pyarrow/io.pxi", line 906, in pyarrow.lib.OSFile._open_readable
  File "pyarrow/error.pxi", line 143, in pyarrow.lib.pyarrow_internal_check_status
  File "pyarrow/error.pxi", line 112, in pyarrow.lib.check_status
FileNotFoundError: [Errno 2] Failed to open local file '/opt/airflow/brooklyn-food-waste/brooklyn.csv'. Detail: [errno 2] No such file or directory
[2022-06-21 16:20:34,631] {taskinstance.py:1400} INFO - Marking task as UP_FOR_RETRY. dag_id=data_ingestion_gcs_dag, task_id=format_to_parquet_task, execution_date=20220621T162027, start_date=20220621T162034, end_date=20220621T162034
[2022-06-21 16:20:34,653] {standard_task_runner.py:97} ERROR - Failed to execute job 32 for task format_to_parquet_task ([Errno 2] Failed to open local file '/opt/airflow/brooklyn-food-waste/brooklyn.csv'. Detail: [errno 2] No such file or directory; 100)
[2022-06-21 16:20:34,678] {local_task_job.py:156} INFO - Task exited with return code 1
[2022-06-21 16:20:34,766] {local_task_job.py:273} INFO - 0 downstream tasks scheduled from follow-on schedule check
