[2022-06-22 13:33:38,255] {taskinstance.py:1159} INFO - Dependencies all met for <TaskInstance: data_ingestion_gcs_dag.local_to_gcs_task manual__2022-06-22T11:55:39.915601+00:00 [queued]>
[2022-06-22 13:33:38,263] {taskinstance.py:1159} INFO - Dependencies all met for <TaskInstance: data_ingestion_gcs_dag.local_to_gcs_task manual__2022-06-22T11:55:39.915601+00:00 [queued]>
[2022-06-22 13:33:38,263] {taskinstance.py:1356} INFO - 
--------------------------------------------------------------------------------
[2022-06-22 13:33:38,263] {taskinstance.py:1357} INFO - Starting attempt 2 of 2
[2022-06-22 13:33:38,263] {taskinstance.py:1358} INFO - 
--------------------------------------------------------------------------------
[2022-06-22 13:33:38,276] {taskinstance.py:1377} INFO - Executing <Task(PythonOperator): local_to_gcs_task> on 2022-06-22 11:55:39.915601+00:00
[2022-06-22 13:33:38,280] {standard_task_runner.py:52} INFO - Started process 88 to run task
[2022-06-22 13:33:38,282] {standard_task_runner.py:79} INFO - Running: ['***', 'tasks', 'run', 'data_ingestion_gcs_dag', 'local_to_gcs_task', 'manual__2022-06-22T11:55:39.915601+00:00', '--job-id', '151', '--raw', '--subdir', 'DAGS_FOLDER/dags.py', '--cfg-path', '/tmp/tmpvoj6hkk7', '--error-file', '/tmp/tmpe6y9hg2x']
[2022-06-22 13:33:38,282] {standard_task_runner.py:80} INFO - Job 151: Subtask local_to_gcs_task
[2022-06-22 13:33:38,330] {task_command.py:370} INFO - Running <TaskInstance: data_ingestion_gcs_dag.local_to_gcs_task manual__2022-06-22T11:55:39.915601+00:00 [running]> on host 1bd671e47a78
[2022-06-22 13:33:38,386] {taskinstance.py:1571} INFO - Exporting the following env vars:
AIRFLOW_CTX_DAG_OWNER=***
AIRFLOW_CTX_DAG_ID=data_ingestion_gcs_dag
AIRFLOW_CTX_TASK_ID=local_to_gcs_task
AIRFLOW_CTX_EXECUTION_DATE=2022-06-22T11:55:39.915601+00:00
AIRFLOW_CTX_TRY_NUMBER=2
AIRFLOW_CTX_DAG_RUN_ID=manual__2022-06-22T11:55:39.915601+00:00
[2022-06-22 13:33:38,398] {taskinstance.py:1889} ERROR - Task failed with exception
Traceback (most recent call last):
  File "/home/airflow/.local/lib/python3.7/site-packages/airflow/operators/python.py", line 171, in execute
    return_value = self.execute_callable()
  File "/home/airflow/.local/lib/python3.7/site-packages/airflow/operators/python.py", line 189, in execute_callable
    return self.python_callable(*self.op_args, **self.op_kwargs)
  File "/opt/airflow/dags/dags.py", line 64, in upload_to_gcs
    blob.upload_from_filename(local_file)
  File "/home/airflow/.local/lib/python3.7/site-packages/google/cloud/storage/blob.py", line 2720, in upload_from_filename
    with open(filename, "rb") as file_obj:
FileNotFoundError: [Errno 2] No such file or directory: '/opt/airflow/brooklyn.parquet'
[2022-06-22 13:33:38,404] {taskinstance.py:1400} INFO - Marking task as FAILED. dag_id=data_ingestion_gcs_dag, task_id=local_to_gcs_task, execution_date=20220622T115539, start_date=20220622T133338, end_date=20220622T133338
[2022-06-22 13:33:38,413] {standard_task_runner.py:97} ERROR - Failed to execute job 151 for task local_to_gcs_task ([Errno 2] No such file or directory: '/opt/airflow/brooklyn.parquet'; 88)
[2022-06-22 13:33:38,454] {local_task_job.py:156} INFO - Task exited with return code 1
[2022-06-22 13:33:38,530] {local_task_job.py:273} INFO - 0 downstream tasks scheduled from follow-on schedule check
