[2022-06-27 16:01:41,815] {taskinstance.py:1159} INFO - Dependencies all met for <TaskInstance: process-food-waste-data.process_data_task manual__2022-06-27T16:01:29.551212+00:00 [queued]>
[2022-06-27 16:01:41,825] {taskinstance.py:1159} INFO - Dependencies all met for <TaskInstance: process-food-waste-data.process_data_task manual__2022-06-27T16:01:29.551212+00:00 [queued]>
[2022-06-27 16:01:41,825] {taskinstance.py:1356} INFO - 
--------------------------------------------------------------------------------
[2022-06-27 16:01:41,825] {taskinstance.py:1357} INFO - Starting attempt 1 of 2
[2022-06-27 16:01:41,825] {taskinstance.py:1358} INFO - 
--------------------------------------------------------------------------------
[2022-06-27 16:01:41,843] {taskinstance.py:1377} INFO - Executing <Task(PythonOperator): process_data_task> on 2022-06-27 16:01:29.551212+00:00
[2022-06-27 16:01:41,850] {clientserver.py:543} INFO - Closing down clientserver connection
[2022-06-27 16:01:41,850] {standard_task_runner.py:52} INFO - Started process 286 to run task
[2022-06-27 16:01:41,854] {standard_task_runner.py:79} INFO - Running: ['***', 'tasks', 'run', 'process-food-waste-data', 'process_data_task', 'manual__2022-06-27T16:01:29.551212+00:00', '--job-id', '404', '--raw', '--subdir', 'DAGS_FOLDER/02_data_process_dag.py', '--cfg-path', '/tmp/tmpmhdc1nkw', '--error-file', '/tmp/tmp_khclblh']
[2022-06-27 16:01:41,855] {standard_task_runner.py:80} INFO - Job 404: Subtask process_data_task
[2022-06-27 16:01:41,912] {task_command.py:370} INFO - Running <TaskInstance: process-food-waste-data.process_data_task manual__2022-06-27T16:01:29.551212+00:00 [running]> on host 526a61f73853
[2022-06-27 16:01:41,992] {taskinstance.py:1571} INFO - Exporting the following env vars:
AIRFLOW_CTX_DAG_OWNER=***
AIRFLOW_CTX_DAG_ID=process-food-waste-data
AIRFLOW_CTX_TASK_ID=process_data_task
AIRFLOW_CTX_EXECUTION_DATE=2022-06-27T16:01:29.551212+00:00
AIRFLOW_CTX_TRY_NUMBER=1
AIRFLOW_CTX_DAG_RUN_ID=manual__2022-06-27T16:01:29.551212+00:00
[2022-06-27 16:01:41,993] {logging_mixin.py:115} INFO - ENTERED FUNCTION
[2022-06-27 16:01:42,689] {clientserver.py:505} INFO - Error while sending or receiving.
Traceback (most recent call last):
  File "/home/airflow/.local/lib/python3.7/site-packages/py4j/clientserver.py", line 503, in send_command
    self.socket.sendall(command.encode("utf-8"))
ConnectionResetError: [Errno 104] Connection reset by peer
[2022-06-27 16:01:42,690] {clientserver.py:543} INFO - Closing down clientserver connection
[2022-06-27 16:01:42,690] {java_gateway.py:1052} INFO - Exception while sending command.
Traceback (most recent call last):
  File "/home/airflow/.local/lib/python3.7/site-packages/py4j/clientserver.py", line 503, in send_command
    self.socket.sendall(command.encode("utf-8"))
ConnectionResetError: [Errno 104] Connection reset by peer

During handling of the above exception, another exception occurred:

Traceback (most recent call last):
  File "/home/airflow/.local/lib/python3.7/site-packages/py4j/java_gateway.py", line 1038, in send_command
    response = connection.send_command(command)
  File "/home/airflow/.local/lib/python3.7/site-packages/py4j/clientserver.py", line 507, in send_command
    "Error while sending", e, proto.ERROR_ON_SEND)
py4j.protocol.Py4JNetworkError: Error while sending
[2022-06-27 16:01:42,694] {clientserver.py:543} INFO - Closing down clientserver connection
[2022-06-27 16:01:48,959] {taskinstance.py:1889} ERROR - Task failed with exception
Traceback (most recent call last):
  File "/home/airflow/.local/lib/python3.7/site-packages/airflow/operators/python.py", line 171, in execute
    return_value = self.execute_callable()
  File "/home/airflow/.local/lib/python3.7/site-packages/airflow/operators/python.py", line 189, in execute_callable
    return self.python_callable(*self.op_args, **self.op_kwargs)
  File "/opt/airflow/dags/scripts/process_food_waste_data.py", line 94, in process_food_waste_data
    df = process_date_columns(df)
  File "/opt/airflow/dags/scripts/process_food_waste_data.py", line 103, in process_date_columns
    df = df.filter(F.len(F.col(col)) == 10)\
AttributeError: module 'pyspark.sql.functions' has no attribute 'len'
[2022-06-27 16:01:48,971] {taskinstance.py:1400} INFO - Marking task as UP_FOR_RETRY. dag_id=process-food-waste-data, task_id=process_data_task, execution_date=20220627T160129, start_date=20220627T160141, end_date=20220627T160148
[2022-06-27 16:01:48,991] {standard_task_runner.py:97} ERROR - Failed to execute job 404 for task process_data_task (module 'pyspark.sql.functions' has no attribute 'len'; 286)
[2022-06-27 16:01:49,017] {local_task_job.py:156} INFO - Task exited with return code 1
[2022-06-27 16:01:49,064] {local_task_job.py:273} INFO - 0 downstream tasks scheduled from follow-on schedule check
