[2022-06-21 17:15:33,489] {taskinstance.py:1159} INFO - Dependencies all met for <TaskInstance: data_ingestion_gcs_dag.format_to_parquet_task manual__2022-06-21T17:15:10.456264+00:00 [queued]>
[2022-06-21 17:15:33,495] {taskinstance.py:1159} INFO - Dependencies all met for <TaskInstance: data_ingestion_gcs_dag.format_to_parquet_task manual__2022-06-21T17:15:10.456264+00:00 [queued]>
[2022-06-21 17:15:33,495] {taskinstance.py:1356} INFO - 
--------------------------------------------------------------------------------
[2022-06-21 17:15:33,495] {taskinstance.py:1357} INFO - Starting attempt 1 of 2
[2022-06-21 17:15:33,495] {taskinstance.py:1358} INFO - 
--------------------------------------------------------------------------------
[2022-06-21 17:15:33,507] {taskinstance.py:1377} INFO - Executing <Task(PythonOperator): format_to_parquet_task> on 2022-06-21 17:15:10.456264+00:00
[2022-06-21 17:15:33,512] {standard_task_runner.py:52} INFO - Started process 154 to run task
[2022-06-21 17:15:33,514] {standard_task_runner.py:79} INFO - Running: ['***', 'tasks', 'run', 'data_ingestion_gcs_dag', 'format_to_parquet_task', 'manual__2022-06-21T17:15:10.456264+00:00', '--job-id', '68', '--raw', '--subdir', 'DAGS_FOLDER/dags.py', '--cfg-path', '/tmp/tmpqrhhadal', '--error-file', '/tmp/tmpvaa3qpq2']
[2022-06-21 17:15:33,516] {standard_task_runner.py:80} INFO - Job 68: Subtask format_to_parquet_task
[2022-06-21 17:15:33,549] {task_command.py:370} INFO - Running <TaskInstance: data_ingestion_gcs_dag.format_to_parquet_task manual__2022-06-21T17:15:10.456264+00:00 [running]> on host 8245915a88cb
[2022-06-21 17:15:33,604] {taskinstance.py:1571} INFO - Exporting the following env vars:
AIRFLOW_CTX_DAG_OWNER=***
AIRFLOW_CTX_DAG_ID=data_ingestion_gcs_dag
AIRFLOW_CTX_TASK_ID=format_to_parquet_task
AIRFLOW_CTX_EXECUTION_DATE=2022-06-21T17:15:10.456264+00:00
AIRFLOW_CTX_TRY_NUMBER=1
AIRFLOW_CTX_DAG_RUN_ID=manual__2022-06-21T17:15:10.456264+00:00
[2022-06-21 17:15:33,605] {taskinstance.py:1889} ERROR - Task failed with exception
Traceback (most recent call last):
  File "/home/airflow/.local/lib/python3.7/site-packages/airflow/operators/python.py", line 171, in execute
    return_value = self.execute_callable()
  File "/home/airflow/.local/lib/python3.7/site-packages/airflow/operators/python.py", line 189, in execute_callable
    return self.python_callable(*self.op_args, **self.op_kwargs)
  File "/opt/airflow/dags/dags.py", line 81, in format_to_parquet
    table = pv.read_csv(src_file)
  File "pyarrow/_csv.pyx", line 881, in pyarrow._csv.read_csv
  File "pyarrow/_csv.pyx", line 774, in pyarrow._csv._get_reader
  File "pyarrow/io.pxi", line 1631, in pyarrow.lib.get_input_stream
  File "pyarrow/io.pxi", line 1602, in pyarrow.lib.get_native_file
  File "pyarrow/io.pxi", line 896, in pyarrow.lib.OSFile.__cinit__
  File "pyarrow/io.pxi", line 906, in pyarrow.lib.OSFile._open_readable
  File "pyarrow/error.pxi", line 143, in pyarrow.lib.pyarrow_internal_check_status
  File "pyarrow/error.pxi", line 112, in pyarrow.lib.check_status
FileNotFoundError: [Errno 2] Failed to open local file '/opt/airflow/brooklyn-food-waste/brooklyn.csv'. Detail: [errno 2] No such file or directory
[2022-06-21 17:15:33,610] {taskinstance.py:1400} INFO - Marking task as UP_FOR_RETRY. dag_id=data_ingestion_gcs_dag, task_id=format_to_parquet_task, execution_date=20220621T171510, start_date=20220621T171533, end_date=20220621T171533
[2022-06-21 17:15:33,619] {standard_task_runner.py:97} ERROR - Failed to execute job 68 for task format_to_parquet_task ([Errno 2] Failed to open local file '/opt/airflow/brooklyn-food-waste/brooklyn.csv'. Detail: [errno 2] No such file or directory; 154)
[2022-06-21 17:15:33,648] {local_task_job.py:156} INFO - Task exited with return code 1
[2022-06-21 17:15:33,688] {local_task_job.py:273} INFO - 0 downstream tasks scheduled from follow-on schedule check
