[2022-06-27 17:17:52,049] {taskinstance.py:1159} INFO - Dependencies all met for <TaskInstance: process-food-waste-data.process_data_task manual__2022-06-27T17:17:47.877777+00:00 [queued]>
[2022-06-27 17:17:52,055] {taskinstance.py:1159} INFO - Dependencies all met for <TaskInstance: process-food-waste-data.process_data_task manual__2022-06-27T17:17:47.877777+00:00 [queued]>
[2022-06-27 17:17:52,055] {taskinstance.py:1356} INFO - 
--------------------------------------------------------------------------------
[2022-06-27 17:17:52,055] {taskinstance.py:1357} INFO - Starting attempt 1 of 2
[2022-06-27 17:17:52,055] {taskinstance.py:1358} INFO - 
--------------------------------------------------------------------------------
[2022-06-27 17:17:52,065] {taskinstance.py:1377} INFO - Executing <Task(PythonOperator): process_data_task> on 2022-06-27 17:17:47.877777+00:00
[2022-06-27 17:17:52,071] {clientserver.py:543} INFO - Closing down clientserver connection
[2022-06-27 17:17:52,070] {standard_task_runner.py:52} INFO - Started process 1943 to run task
[2022-06-27 17:17:52,073] {standard_task_runner.py:79} INFO - Running: ['***', 'tasks', 'run', 'process-food-waste-data', 'process_data_task', 'manual__2022-06-27T17:17:47.877777+00:00', '--job-id', '467', '--raw', '--subdir', 'DAGS_FOLDER/02_data_process_dag.py', '--cfg-path', '/tmp/tmpsulp_bk1', '--error-file', '/tmp/tmpm2lhlrv2']
[2022-06-27 17:17:52,074] {standard_task_runner.py:80} INFO - Job 467: Subtask process_data_task
[2022-06-27 17:17:52,107] {task_command.py:370} INFO - Running <TaskInstance: process-food-waste-data.process_data_task manual__2022-06-27T17:17:47.877777+00:00 [running]> on host d3c6daab9be3
[2022-06-27 17:17:52,155] {taskinstance.py:1571} INFO - Exporting the following env vars:
AIRFLOW_CTX_DAG_OWNER=***
AIRFLOW_CTX_DAG_ID=process-food-waste-data
AIRFLOW_CTX_TASK_ID=process_data_task
AIRFLOW_CTX_EXECUTION_DATE=2022-06-27T17:17:47.877777+00:00
AIRFLOW_CTX_TRY_NUMBER=1
AIRFLOW_CTX_DAG_RUN_ID=manual__2022-06-27T17:17:47.877777+00:00
[2022-06-27 17:17:52,156] {logging_mixin.py:115} INFO - ENTERED FUNCTION
[2022-06-27 17:17:52,199] {clientserver.py:505} INFO - Error while sending or receiving.
Traceback (most recent call last):
  File "/home/airflow/.local/lib/python3.7/site-packages/py4j/clientserver.py", line 503, in send_command
    self.socket.sendall(command.encode("utf-8"))
ConnectionResetError: [Errno 104] Connection reset by peer
[2022-06-27 17:17:52,200] {clientserver.py:543} INFO - Closing down clientserver connection
[2022-06-27 17:17:52,200] {java_gateway.py:1052} INFO - Exception while sending command.
Traceback (most recent call last):
  File "/home/airflow/.local/lib/python3.7/site-packages/py4j/clientserver.py", line 503, in send_command
    self.socket.sendall(command.encode("utf-8"))
ConnectionResetError: [Errno 104] Connection reset by peer

During handling of the above exception, another exception occurred:

Traceback (most recent call last):
  File "/home/airflow/.local/lib/python3.7/site-packages/py4j/java_gateway.py", line 1038, in send_command
    response = connection.send_command(command)
  File "/home/airflow/.local/lib/python3.7/site-packages/py4j/clientserver.py", line 507, in send_command
    "Error while sending", e, proto.ERROR_ON_SEND)
py4j.protocol.Py4JNetworkError: Error while sending
[2022-06-27 17:17:52,201] {clientserver.py:543} INFO - Closing down clientserver connection
[2022-06-27 17:17:58,925] {logging_mixin.py:115} INFO - There were  8  records eliminated by ensuring date format.
[2022-06-27 17:18:05,743] {taskinstance.py:1889} ERROR - Task failed with exception
Traceback (most recent call last):
  File "/home/airflow/.local/lib/python3.7/site-packages/airflow/operators/python.py", line 171, in execute
    return_value = self.execute_callable()
  File "/home/airflow/.local/lib/python3.7/site-packages/airflow/operators/python.py", line 189, in execute_callable
    return self.python_callable(*self.op_args, **self.op_kwargs)
  File "/opt/airflow/dags/scripts/process_food_waste_data.py", line 98, in process_food_waste_data
    df.write.parquet(f"gs://{BUCKET}/{processed_folder}/food_waste")\
AttributeError: 'NoneType' object has no attribute 'schema'
[2022-06-27 17:18:05,749] {taskinstance.py:1400} INFO - Marking task as UP_FOR_RETRY. dag_id=process-food-waste-data, task_id=process_data_task, execution_date=20220627T171747, start_date=20220627T171752, end_date=20220627T171805
[2022-06-27 17:18:05,758] {standard_task_runner.py:97} ERROR - Failed to execute job 467 for task process_data_task ('NoneType' object has no attribute 'schema'; 1943)
[2022-06-27 17:18:05,781] {local_task_job.py:156} INFO - Task exited with return code 1
[2022-06-27 17:18:05,817] {local_task_job.py:273} INFO - 0 downstream tasks scheduled from follow-on schedule check
