[2022-06-22 11:29:10,059] {taskinstance.py:1159} INFO - Dependencies all met for <TaskInstance: data_ingestion_gcs_dag.local_to_gcs_task scheduled__2020-02-01T00:00:00+00:00 [queued]>
[2022-06-22 11:29:10,065] {taskinstance.py:1159} INFO - Dependencies all met for <TaskInstance: data_ingestion_gcs_dag.local_to_gcs_task scheduled__2020-02-01T00:00:00+00:00 [queued]>
[2022-06-22 11:29:10,065] {taskinstance.py:1356} INFO - 
--------------------------------------------------------------------------------
[2022-06-22 11:29:10,065] {taskinstance.py:1357} INFO - Starting attempt 1 of 2
[2022-06-22 11:29:10,065] {taskinstance.py:1358} INFO - 
--------------------------------------------------------------------------------
[2022-06-22 11:29:10,077] {taskinstance.py:1377} INFO - Executing <Task(PythonOperator): local_to_gcs_task> on 2020-02-01 00:00:00+00:00
[2022-06-22 11:29:10,082] {standard_task_runner.py:52} INFO - Started process 644 to run task
[2022-06-22 11:29:10,084] {standard_task_runner.py:79} INFO - Running: ['***', 'tasks', 'run', 'data_ingestion_gcs_dag', 'local_to_gcs_task', 'scheduled__2020-02-01T00:00:00+00:00', '--job-id', '122', '--raw', '--subdir', 'DAGS_FOLDER/dags.py', '--cfg-path', '/tmp/tmpi34r4ogo', '--error-file', '/tmp/tmpawk9mp5i']
[2022-06-22 11:29:10,084] {standard_task_runner.py:80} INFO - Job 122: Subtask local_to_gcs_task
[2022-06-22 11:29:10,117] {task_command.py:370} INFO - Running <TaskInstance: data_ingestion_gcs_dag.local_to_gcs_task scheduled__2020-02-01T00:00:00+00:00 [running]> on host 69b874fb3dd4
[2022-06-22 11:29:10,174] {taskinstance.py:1571} INFO - Exporting the following env vars:
AIRFLOW_CTX_DAG_OWNER=***
AIRFLOW_CTX_DAG_ID=data_ingestion_gcs_dag
AIRFLOW_CTX_TASK_ID=local_to_gcs_task
AIRFLOW_CTX_EXECUTION_DATE=2020-02-01T00:00:00+00:00
AIRFLOW_CTX_TRY_NUMBER=1
AIRFLOW_CTX_DAG_RUN_ID=scheduled__2020-02-01T00:00:00+00:00
[2022-06-22 11:29:10,175] {taskinstance.py:1889} ERROR - Task failed with exception
Traceback (most recent call last):
  File "/home/airflow/.local/lib/python3.7/site-packages/airflow/operators/python.py", line 171, in execute
    return_value = self.execute_callable()
  File "/home/airflow/.local/lib/python3.7/site-packages/airflow/operators/python.py", line 189, in execute_callable
    return self.python_callable(*self.op_args, **self.op_kwargs)
  File "/opt/airflow/dags/dags.py", line 60, in upload_to_gcs
    client = storage.Client()
  File "/home/airflow/.local/lib/python3.7/site-packages/google/cloud/storage/client.py", line 128, in __init__
    _http=_http,
  File "/home/airflow/.local/lib/python3.7/site-packages/google/cloud/client/__init__.py", line 320, in __init__
    _ClientProjectMixin.__init__(self, project=project, credentials=credentials)
  File "/home/airflow/.local/lib/python3.7/site-packages/google/cloud/client/__init__.py", line 268, in __init__
    project = self._determine_default(project)
  File "/home/airflow/.local/lib/python3.7/site-packages/google/cloud/client/__init__.py", line 287, in _determine_default
    return _determine_default_project(project)
  File "/home/airflow/.local/lib/python3.7/site-packages/google/cloud/_helpers/__init__.py", line 152, in _determine_default_project
    _, project = google.auth.default()
  File "/home/airflow/.local/lib/python3.7/site-packages/google/auth/_default.py", line 546, in default
    credentials, project_id = checker()
  File "/home/airflow/.local/lib/python3.7/site-packages/google/auth/_default.py", line 539, in <lambda>
    lambda: _get_explicit_environ_credentials(quota_project_id=quota_project_id),
  File "/home/airflow/.local/lib/python3.7/site-packages/google/auth/_default.py", line 219, in _get_explicit_environ_credentials
    os.environ[environment_vars.CREDENTIALS], quota_project_id=quota_project_id
  File "/home/airflow/.local/lib/python3.7/site-packages/google/auth/_default.py", line 118, in load_credentials_from_file
    "File {} was not found.".format(filename)
google.auth.exceptions.DefaultCredentialsError: File /.google/credentials/google_credentials.json was not found.
[2022-06-22 11:29:10,182] {taskinstance.py:1400} INFO - Marking task as UP_FOR_RETRY. dag_id=data_ingestion_gcs_dag, task_id=local_to_gcs_task, execution_date=20200201T000000, start_date=20220622T112910, end_date=20220622T112910
[2022-06-22 11:29:10,190] {standard_task_runner.py:97} ERROR - Failed to execute job 122 for task local_to_gcs_task (File /.google/credentials/google_credentials.json was not found.; 644)
[2022-06-22 11:29:10,215] {local_task_job.py:156} INFO - Task exited with return code 1
[2022-06-22 11:29:10,244] {local_task_job.py:273} INFO - 0 downstream tasks scheduled from follow-on schedule check
