[2022-06-22 11:38:43,336] {taskinstance.py:1159} INFO - Dependencies all met for <TaskInstance: data_ingestion_gcs_dag.local_to_gcs_task manual__2022-06-22T11:32:15.707774+00:00 [queued]>
[2022-06-22 11:38:43,349] {taskinstance.py:1159} INFO - Dependencies all met for <TaskInstance: data_ingestion_gcs_dag.local_to_gcs_task manual__2022-06-22T11:32:15.707774+00:00 [queued]>
[2022-06-22 11:38:43,349] {taskinstance.py:1356} INFO - 
--------------------------------------------------------------------------------
[2022-06-22 11:38:43,349] {taskinstance.py:1357} INFO - Starting attempt 1 of 2
[2022-06-22 11:38:43,349] {taskinstance.py:1358} INFO - 
--------------------------------------------------------------------------------
[2022-06-22 11:38:43,371] {taskinstance.py:1377} INFO - Executing <Task(PythonOperator): local_to_gcs_task> on 2022-06-22 11:32:15.707774+00:00
[2022-06-22 11:38:43,378] {standard_task_runner.py:52} INFO - Started process 206 to run task
[2022-06-22 11:38:43,380] {standard_task_runner.py:79} INFO - Running: ['***', 'tasks', 'run', 'data_ingestion_gcs_dag', 'local_to_gcs_task', 'manual__2022-06-22T11:32:15.707774+00:00', '--job-id', '138', '--raw', '--subdir', 'DAGS_FOLDER/dags.py', '--cfg-path', '/tmp/tmpnc3oylts', '--error-file', '/tmp/tmpv1tcd9ly']
[2022-06-22 11:38:43,381] {standard_task_runner.py:80} INFO - Job 138: Subtask local_to_gcs_task
[2022-06-22 11:38:43,431] {task_command.py:370} INFO - Running <TaskInstance: data_ingestion_gcs_dag.local_to_gcs_task manual__2022-06-22T11:32:15.707774+00:00 [running]> on host cb3a0c5d3ca1
[2022-06-22 11:38:43,519] {taskinstance.py:1571} INFO - Exporting the following env vars:
AIRFLOW_CTX_DAG_OWNER=***
AIRFLOW_CTX_DAG_ID=data_ingestion_gcs_dag
AIRFLOW_CTX_TASK_ID=local_to_gcs_task
AIRFLOW_CTX_EXECUTION_DATE=2022-06-22T11:32:15.707774+00:00
AIRFLOW_CTX_TRY_NUMBER=1
AIRFLOW_CTX_DAG_RUN_ID=manual__2022-06-22T11:32:15.707774+00:00
[2022-06-22 11:38:43,920] {taskinstance.py:1889} ERROR - Task failed with exception
Traceback (most recent call last):
  File "/home/airflow/.local/lib/python3.7/site-packages/google/cloud/storage/blob.py", line 2594, in upload_from_file
    retry=retry,
  File "/home/airflow/.local/lib/python3.7/site-packages/google/cloud/storage/blob.py", line 2396, in _do_upload
    retry=retry,
  File "/home/airflow/.local/lib/python3.7/site-packages/google/cloud/storage/blob.py", line 1917, in _do_multipart_upload
    transport, data, object_metadata, content_type, timeout=timeout
  File "/home/airflow/.local/lib/python3.7/site-packages/google/resumable_media/requests/upload.py", line 154, in transmit
    retriable_request, self._get_status_code, self._retry_strategy
  File "/home/airflow/.local/lib/python3.7/site-packages/google/resumable_media/requests/_request_helpers.py", line 148, in wait_and_retry
    response = func()
  File "/home/airflow/.local/lib/python3.7/site-packages/google/resumable_media/requests/upload.py", line 149, in retriable_request
    self._process_response(result)
  File "/home/airflow/.local/lib/python3.7/site-packages/google/resumable_media/_upload.py", line 114, in _process_response
    _helpers.require_status_code(response, (http.client.OK,), self._get_status_code)
  File "/home/airflow/.local/lib/python3.7/site-packages/google/resumable_media/_helpers.py", line 110, in require_status_code
    *status_codes
google.resumable_media.common.InvalidResponse: ('Request failed with status code', 403, 'Expected one of', <HTTPStatus.OK: 200>)

During handling of the above exception, another exception occurred:

Traceback (most recent call last):
  File "/home/airflow/.local/lib/python3.7/site-packages/airflow/operators/python.py", line 171, in execute
    return_value = self.execute_callable()
  File "/home/airflow/.local/lib/python3.7/site-packages/airflow/operators/python.py", line 189, in execute_callable
    return self.python_callable(*self.op_args, **self.op_kwargs)
  File "/opt/airflow/dags/dags.py", line 64, in upload_to_gcs
    blob.upload_from_filename(local_file)
  File "/home/airflow/.local/lib/python3.7/site-packages/google/cloud/storage/blob.py", line 2735, in upload_from_filename
    retry=retry,
  File "/home/airflow/.local/lib/python3.7/site-packages/google/cloud/storage/blob.py", line 2598, in upload_from_file
    _raise_from_invalid_response(exc)
  File "/home/airflow/.local/lib/python3.7/site-packages/google/cloud/storage/blob.py", line 4470, in _raise_from_invalid_response
    raise exceptions.from_http_status(response.status_code, message, response=response)
google.api_core.exceptions.Forbidden: 403 POST https://storage.googleapis.com/upload/storage/v1/b/dtc-project-data_dtc-project-ritaafranco/o?uploadType=multipart: {
  "error": {
    "code": 403,
    "message": "dtc-de-user@dtc-data-engineering-zoomcamp.iam.gserviceaccount.com does not have storage.objects.create access to the Google Cloud Storage object.",
    "errors": [
      {
        "message": "dtc-de-user@dtc-data-engineering-zoomcamp.iam.gserviceaccount.com does not have storage.objects.create access to the Google Cloud Storage object.",
        "domain": "global",
        "reason": "forbidden"
      }
    ]
  }
}
: ('Request failed with status code', 403, 'Expected one of', <HTTPStatus.OK: 200>)
[2022-06-22 11:38:43,928] {taskinstance.py:1400} INFO - Marking task as UP_FOR_RETRY. dag_id=data_ingestion_gcs_dag, task_id=local_to_gcs_task, execution_date=20220622T113215, start_date=20220622T113843, end_date=20220622T113843
[2022-06-22 11:38:43,938] {standard_task_runner.py:97} ERROR - Failed to execute job 138 for task local_to_gcs_task (403 POST https://storage.googleapis.com/upload/storage/v1/b/dtc-project-data_dtc-project-ritaafranco/o?uploadType=multipart: {
  "error": {
    "code": 403,
    "message": "dtc-de-user@dtc-data-engineering-zoomcamp.iam.gserviceaccount.com does not have storage.objects.create access to the Google Cloud Storage object.",
    "errors": [
      {
        "message": "dtc-de-user@dtc-data-engineering-zoomcamp.iam.gserviceaccount.com does not have storage.objects.create access to the Google Cloud Storage object.",
        "domain": "global",
        "reason": "forbidden"
      }
    ]
  }
}
: ('Request failed with status code', 403, 'Expected one of', <HTTPStatus.OK: 200>); 206)
[2022-06-22 11:38:43,953] {local_task_job.py:156} INFO - Task exited with return code 1
[2022-06-22 11:38:43,987] {local_task_job.py:273} INFO - 0 downstream tasks scheduled from follow-on schedule check
