[2022-06-21 14:47:55,092] {taskinstance.py:1159} INFO - Dependencies all met for <TaskInstance: data_ingestion_gcs_dag.download_dataset_task scheduled__2022-06-20T00:00:00+00:00 [queued]>
[2022-06-21 14:47:55,107] {taskinstance.py:1159} INFO - Dependencies all met for <TaskInstance: data_ingestion_gcs_dag.download_dataset_task scheduled__2022-06-20T00:00:00+00:00 [queued]>
[2022-06-21 14:47:55,107] {taskinstance.py:1356} INFO - 
--------------------------------------------------------------------------------
[2022-06-21 14:47:55,108] {taskinstance.py:1357} INFO - Starting attempt 1 of 2
[2022-06-21 14:47:55,108] {taskinstance.py:1358} INFO - 
--------------------------------------------------------------------------------
[2022-06-21 14:47:55,131] {taskinstance.py:1377} INFO - Executing <Task(PythonOperator): download_dataset_task> on 2022-06-20 00:00:00+00:00
[2022-06-21 14:47:55,138] {standard_task_runner.py:52} INFO - Started process 95 to run task
[2022-06-21 14:47:55,142] {standard_task_runner.py:79} INFO - Running: ['***', 'tasks', 'run', 'data_ingestion_gcs_dag', 'download_dataset_task', 'scheduled__2022-06-20T00:00:00+00:00', '--job-id', '5', '--raw', '--subdir', 'DAGS_FOLDER/dags.py', '--cfg-path', '/tmp/tmpev4_9you', '--error-file', '/tmp/tmp4zwb7k0j']
[2022-06-21 14:47:55,144] {standard_task_runner.py:80} INFO - Job 5: Subtask download_dataset_task
[2022-06-21 14:47:55,216] {task_command.py:370} INFO - Running <TaskInstance: data_ingestion_gcs_dag.download_dataset_task scheduled__2022-06-20T00:00:00+00:00 [running]> on host 247b3af9617b
[2022-06-21 14:47:55,334] {taskinstance.py:1571} INFO - Exporting the following env vars:
AIRFLOW_CTX_DAG_OWNER=***
AIRFLOW_CTX_DAG_ID=data_ingestion_gcs_dag
AIRFLOW_CTX_TASK_ID=download_dataset_task
AIRFLOW_CTX_EXECUTION_DATE=2022-06-20T00:00:00+00:00
AIRFLOW_CTX_TRY_NUMBER=1
AIRFLOW_CTX_DAG_RUN_ID=scheduled__2022-06-20T00:00:00+00:00
[2022-06-21 14:47:55,337] {taskinstance.py:1889} ERROR - Task failed with exception
Traceback (most recent call last):
  File "/home/airflow/.local/lib/python3.7/site-packages/airflow/operators/python.py", line 171, in execute
    return_value = self.execute_callable()
  File "/home/airflow/.local/lib/python3.7/site-packages/airflow/operators/python.py", line 189, in execute_callable
    return self.python_callable(*self.op_args, **self.op_kwargs)
  File "/opt/airflow/dags/dags.py", line 25, in download_data
    import opendatasets as op
ModuleNotFoundError: No module named 'opendatasets'
[2022-06-21 14:47:55,348] {taskinstance.py:1400} INFO - Marking task as UP_FOR_RETRY. dag_id=data_ingestion_gcs_dag, task_id=download_dataset_task, execution_date=20220620T000000, start_date=20220621T144755, end_date=20220621T144755
[2022-06-21 14:47:55,365] {standard_task_runner.py:97} ERROR - Failed to execute job 5 for task download_dataset_task (No module named 'opendatasets'; 95)
[2022-06-21 14:47:55,394] {local_task_job.py:156} INFO - Task exited with return code 1
[2022-06-21 14:47:55,464] {local_task_job.py:273} INFO - 0 downstream tasks scheduled from follow-on schedule check
