[2022-06-27 13:13:18,720] {taskinstance.py:1159} INFO - Dependencies all met for <TaskInstance: process-food-waste-data.process_data_task manual__2022-06-27T13:13:14.229182+00:00 [queued]>
[2022-06-27 13:13:18,725] {taskinstance.py:1159} INFO - Dependencies all met for <TaskInstance: process-food-waste-data.process_data_task manual__2022-06-27T13:13:14.229182+00:00 [queued]>
[2022-06-27 13:13:18,725] {taskinstance.py:1356} INFO - 
--------------------------------------------------------------------------------
[2022-06-27 13:13:18,725] {taskinstance.py:1357} INFO - Starting attempt 1 of 2
[2022-06-27 13:13:18,725] {taskinstance.py:1358} INFO - 
--------------------------------------------------------------------------------
[2022-06-27 13:13:18,738] {taskinstance.py:1377} INFO - Executing <Task(PythonOperator): process_data_task> on 2022-06-27 13:13:14.229182+00:00
[2022-06-27 13:13:18,744] {clientserver.py:543} INFO - Closing down clientserver connection
[2022-06-27 13:13:18,744] {standard_task_runner.py:52} INFO - Started process 6533 to run task
[2022-06-27 13:13:18,747] {standard_task_runner.py:79} INFO - Running: ['***', 'tasks', 'run', 'process-food-waste-data', 'process_data_task', 'manual__2022-06-27T13:13:14.229182+00:00', '--job-id', '374', '--raw', '--subdir', 'DAGS_FOLDER/02_data_process_dag.py', '--cfg-path', '/tmp/tmp92kzv59n', '--error-file', '/tmp/tmpy640emip']
[2022-06-27 13:13:18,748] {standard_task_runner.py:80} INFO - Job 374: Subtask process_data_task
[2022-06-27 13:13:18,785] {task_command.py:370} INFO - Running <TaskInstance: process-food-waste-data.process_data_task manual__2022-06-27T13:13:14.229182+00:00 [running]> on host 78ff5d0f8165
[2022-06-27 13:13:18,836] {taskinstance.py:1571} INFO - Exporting the following env vars:
AIRFLOW_CTX_DAG_OWNER=***
AIRFLOW_CTX_DAG_ID=process-food-waste-data
AIRFLOW_CTX_TASK_ID=process_data_task
AIRFLOW_CTX_EXECUTION_DATE=2022-06-27T13:13:14.229182+00:00
AIRFLOW_CTX_TRY_NUMBER=1
AIRFLOW_CTX_DAG_RUN_ID=manual__2022-06-27T13:13:14.229182+00:00
[2022-06-27 13:13:18,837] {logging_mixin.py:115} INFO - ENTERED FUNCTION
[2022-06-27 13:13:18,838] {logging_mixin.py:115} INFO - gs://dtc-project-data_dtc-project-ritaafranco/raw/brooklyn.parquet
[2022-06-27 13:13:18,860] {clientserver.py:505} INFO - Error while sending or receiving.
Traceback (most recent call last):
  File "/home/airflow/.local/lib/python3.7/site-packages/py4j/clientserver.py", line 503, in send_command
    self.socket.sendall(command.encode("utf-8"))
ConnectionResetError: [Errno 104] Connection reset by peer
[2022-06-27 13:13:18,861] {clientserver.py:543} INFO - Closing down clientserver connection
[2022-06-27 13:13:18,861] {java_gateway.py:1052} INFO - Exception while sending command.
Traceback (most recent call last):
  File "/home/airflow/.local/lib/python3.7/site-packages/py4j/clientserver.py", line 503, in send_command
    self.socket.sendall(command.encode("utf-8"))
ConnectionResetError: [Errno 104] Connection reset by peer

During handling of the above exception, another exception occurred:

Traceback (most recent call last):
  File "/home/airflow/.local/lib/python3.7/site-packages/py4j/java_gateway.py", line 1038, in send_command
    response = connection.send_command(command)
  File "/home/airflow/.local/lib/python3.7/site-packages/py4j/clientserver.py", line 507, in send_command
    "Error while sending", e, proto.ERROR_ON_SEND)
py4j.protocol.Py4JNetworkError: Error while sending
[2022-06-27 13:13:18,863] {clientserver.py:543} INFO - Closing down clientserver connection
[2022-06-27 13:13:23,266] {logging_mixin.py:115} INFO - df read -------------
[2022-06-27 13:13:25,190] {logging_mixin.py:115} INFO - Row(id='5e31d5503b85a2e63d634187', date_collected=datetime.date(2020, 1, 27), retailer_type='counter service', retailer_detail='ready-to-eat and prepackaged health food', food_type='ready-to-eat', food_detail='organic oatmeal', label_type='sticker', label_language='use by', label_date='2020-01-28', approximate_dollar_value=5.25, image_id='IMG_1872', collection_lat=40.69453, collection_long=-73.99447, label_explanation='')
[2022-06-27 13:13:25,198] {taskinstance.py:1889} ERROR - Task failed with exception
Traceback (most recent call last):
  File "/home/airflow/.local/lib/python3.7/site-packages/airflow/operators/python.py", line 171, in execute
    return_value = self.execute_callable()
  File "/home/airflow/.local/lib/python3.7/site-packages/airflow/operators/python.py", line 189, in execute_callable
    return self.python_callable(*self.op_args, **self.op_kwargs)
  File "/opt/airflow/dags/scripts/process_food_waste_data.py", line 100, in process_food_waste_data
    print(df.shape)
  File "/opt/airflow/spark/spark-3.2.1-bin-hadoop3.2/python/pyspark/sql/dataframe.py", line 1660, in __getattr__
    "'%s' object has no attribute '%s'" % (self.__class__.__name__, name))
AttributeError: 'DataFrame' object has no attribute 'shape'
[2022-06-27 13:13:25,206] {taskinstance.py:1400} INFO - Marking task as UP_FOR_RETRY. dag_id=process-food-waste-data, task_id=process_data_task, execution_date=20220627T131314, start_date=20220627T131318, end_date=20220627T131325
[2022-06-27 13:13:25,219] {standard_task_runner.py:97} ERROR - Failed to execute job 374 for task process_data_task ('DataFrame' object has no attribute 'shape'; 6533)
[2022-06-27 13:13:25,259] {local_task_job.py:156} INFO - Task exited with return code 1
[2022-06-27 13:13:25,282] {local_task_job.py:273} INFO - 0 downstream tasks scheduled from follow-on schedule check
