[2022-06-27 17:25:37,924] {taskinstance.py:1159} INFO - Dependencies all met for <TaskInstance: process-food-waste-data.process_data_task manual__2022-06-27T17:20:12.965861+00:00 [queued]>
[2022-06-27 17:25:37,930] {taskinstance.py:1159} INFO - Dependencies all met for <TaskInstance: process-food-waste-data.process_data_task manual__2022-06-27T17:20:12.965861+00:00 [queued]>
[2022-06-27 17:25:37,930] {taskinstance.py:1356} INFO - 
--------------------------------------------------------------------------------
[2022-06-27 17:25:37,930] {taskinstance.py:1357} INFO - Starting attempt 2 of 2
[2022-06-27 17:25:37,930] {taskinstance.py:1358} INFO - 
--------------------------------------------------------------------------------
[2022-06-27 17:25:37,943] {taskinstance.py:1377} INFO - Executing <Task(PythonOperator): process_data_task> on 2022-06-27 17:20:12.965861+00:00
[2022-06-27 17:25:37,949] {clientserver.py:543} INFO - Closing down clientserver connection
[2022-06-27 17:25:37,949] {standard_task_runner.py:52} INFO - Started process 2842 to run task
[2022-06-27 17:25:37,952] {standard_task_runner.py:79} INFO - Running: ['***', 'tasks', 'run', 'process-food-waste-data', 'process_data_task', 'manual__2022-06-27T17:20:12.965861+00:00', '--job-id', '475', '--raw', '--subdir', 'DAGS_FOLDER/02_data_process_dag.py', '--cfg-path', '/tmp/tmps5tdnsly', '--error-file', '/tmp/tmpwlgmor_d']
[2022-06-27 17:25:37,953] {standard_task_runner.py:80} INFO - Job 475: Subtask process_data_task
[2022-06-27 17:25:37,985] {task_command.py:370} INFO - Running <TaskInstance: process-food-waste-data.process_data_task manual__2022-06-27T17:20:12.965861+00:00 [running]> on host d3c6daab9be3
[2022-06-27 17:25:38,038] {taskinstance.py:1571} INFO - Exporting the following env vars:
AIRFLOW_CTX_DAG_OWNER=***
AIRFLOW_CTX_DAG_ID=process-food-waste-data
AIRFLOW_CTX_TASK_ID=process_data_task
AIRFLOW_CTX_EXECUTION_DATE=2022-06-27T17:20:12.965861+00:00
AIRFLOW_CTX_TRY_NUMBER=2
AIRFLOW_CTX_DAG_RUN_ID=manual__2022-06-27T17:20:12.965861+00:00
[2022-06-27 17:25:38,039] {logging_mixin.py:115} INFO - ENTERED FUNCTION
[2022-06-27 17:25:38,042] {clientserver.py:505} INFO - Error while sending or receiving.
Traceback (most recent call last):
  File "/home/airflow/.local/lib/python3.7/site-packages/py4j/clientserver.py", line 503, in send_command
    self.socket.sendall(command.encode("utf-8"))
ConnectionResetError: [Errno 104] Connection reset by peer
[2022-06-27 17:25:38,042] {clientserver.py:543} INFO - Closing down clientserver connection
[2022-06-27 17:25:38,042] {java_gateway.py:1052} INFO - Exception while sending command.
Traceback (most recent call last):
  File "/home/airflow/.local/lib/python3.7/site-packages/py4j/clientserver.py", line 503, in send_command
    self.socket.sendall(command.encode("utf-8"))
ConnectionResetError: [Errno 104] Connection reset by peer

During handling of the above exception, another exception occurred:

Traceback (most recent call last):
  File "/home/airflow/.local/lib/python3.7/site-packages/py4j/java_gateway.py", line 1038, in send_command
    response = connection.send_command(command)
  File "/home/airflow/.local/lib/python3.7/site-packages/py4j/clientserver.py", line 507, in send_command
    "Error while sending", e, proto.ERROR_ON_SEND)
py4j.protocol.Py4JNetworkError: Error while sending
[2022-06-27 17:25:38,044] {clientserver.py:543} INFO - Closing down clientserver connection
[2022-06-27 17:25:43,915] {logging_mixin.py:115} INFO - There were  8  records eliminated by ensuring date format.
[2022-06-27 17:25:44,507] {logging_mixin.py:115} INFO - [Row(date_collected=datetime.date(2020, 1, 27), retailer_type='counter service', retailer_detail='ready-to-eat and prepackaged health food', food_type='ready-to-eat', food_detail='organic oatmeal', label_type='sticker', label_language='use by', label_date=datetime.date(2020, 1, 28), approximate_dollar_value=5.25, collection_lat=40.69453, collection_long=-73.99447, label_explanation='', no_days_untill_expire=-1)]
[2022-06-27 17:25:44,639] {taskinstance.py:1889} ERROR - Task failed with exception
Traceback (most recent call last):
  File "/home/airflow/.local/lib/python3.7/site-packages/airflow/operators/python.py", line 171, in execute
    return_value = self.execute_callable()
  File "/home/airflow/.local/lib/python3.7/site-packages/airflow/operators/python.py", line 189, in execute_callable
    return self.python_callable(*self.op_args, **self.op_kwargs)
  File "/opt/airflow/dags/scripts/process_food_waste_data.py", line 98, in process_food_waste_data
    df.write.parquet(f"gs://{BUCKET}/{processed_folder}/food_waste")\
  File "/opt/airflow/spark/spark-3.2.1-bin-hadoop3.2/python/pyspark/sql/readwriter.py", line 885, in parquet
    self._jwrite.parquet(path)
  File "/home/airflow/.local/lib/python3.7/site-packages/py4j/java_gateway.py", line 1322, in __call__
    answer, self.gateway_client, self.target_id, self.name)
  File "/opt/airflow/spark/spark-3.2.1-bin-hadoop3.2/python/pyspark/sql/utils.py", line 117, in deco
    raise converted from None
pyspark.sql.utils.AnalysisException: path gs://dtc-project-data_dtc-project-ritaafranco/processed/food_waste already exists.
[2022-06-27 17:25:44,647] {taskinstance.py:1400} INFO - Marking task as FAILED. dag_id=process-food-waste-data, task_id=process_data_task, execution_date=20220627T172012, start_date=20220627T172537, end_date=20220627T172544
[2022-06-27 17:25:44,656] {standard_task_runner.py:97} ERROR - Failed to execute job 475 for task process_data_task (path gs://dtc-project-data_dtc-project-ritaafranco/processed/food_waste already exists.; 2842)
[2022-06-27 17:25:44,701] {local_task_job.py:156} INFO - Task exited with return code 1
[2022-06-27 17:25:44,723] {local_task_job.py:273} INFO - 0 downstream tasks scheduled from follow-on schedule check
