[2022-06-21 16:37:26,938] {taskinstance.py:1159} INFO - Dependencies all met for <TaskInstance: data_ingestion_gcs_dag.download_dataset_task manual__2022-06-21T16:32:22.311646+00:00 [queued]>
[2022-06-21 16:37:26,945] {taskinstance.py:1159} INFO - Dependencies all met for <TaskInstance: data_ingestion_gcs_dag.download_dataset_task manual__2022-06-21T16:32:22.311646+00:00 [queued]>
[2022-06-21 16:37:26,945] {taskinstance.py:1356} INFO - 
--------------------------------------------------------------------------------
[2022-06-21 16:37:26,945] {taskinstance.py:1357} INFO - Starting attempt 2 of 2
[2022-06-21 16:37:26,945] {taskinstance.py:1358} INFO - 
--------------------------------------------------------------------------------
[2022-06-21 16:37:26,955] {taskinstance.py:1377} INFO - Executing <Task(PythonOperator): download_dataset_task> on 2022-06-21 16:32:22.311646+00:00
[2022-06-21 16:37:26,962] {standard_task_runner.py:52} INFO - Started process 349 to run task
[2022-06-21 16:37:26,964] {standard_task_runner.py:79} INFO - Running: ['***', 'tasks', 'run', 'data_ingestion_gcs_dag', 'download_dataset_task', 'manual__2022-06-21T16:32:22.311646+00:00', '--job-id', '41', '--raw', '--subdir', 'DAGS_FOLDER/dags.py', '--cfg-path', '/tmp/tmptmco89gr', '--error-file', '/tmp/tmpt2rcg66c']
[2022-06-21 16:37:26,966] {standard_task_runner.py:80} INFO - Job 41: Subtask download_dataset_task
[2022-06-21 16:37:27,023] {task_command.py:370} INFO - Running <TaskInstance: data_ingestion_gcs_dag.download_dataset_task manual__2022-06-21T16:32:22.311646+00:00 [running]> on host 4313655e2064
[2022-06-21 16:37:27,075] {taskinstance.py:1571} INFO - Exporting the following env vars:
AIRFLOW_CTX_DAG_OWNER=***
AIRFLOW_CTX_DAG_ID=data_ingestion_gcs_dag
AIRFLOW_CTX_TASK_ID=download_dataset_task
AIRFLOW_CTX_EXECUTION_DATE=2022-06-21T16:32:22.311646+00:00
AIRFLOW_CTX_TRY_NUMBER=2
AIRFLOW_CTX_DAG_RUN_ID=manual__2022-06-21T16:32:22.311646+00:00
[2022-06-21 16:37:27,084] {taskinstance.py:1889} ERROR - Task failed with exception
Traceback (most recent call last):
  File "/home/airflow/.local/lib/python3.7/site-packages/airflow/operators/python.py", line 171, in execute
    return_value = self.execute_callable()
  File "/home/airflow/.local/lib/python3.7/site-packages/airflow/operators/python.py", line 189, in execute_callable
    return self.python_callable(*self.op_args, **self.op_kwargs)
  File "/opt/airflow/dags/dags.py", line 72, in download_data
    from kaggle.api.kaggle_api_extended import KaggleApi
  File "/home/airflow/.local/lib/python3.7/site-packages/kaggle/__init__.py", line 23, in <module>
    api.authenticate()
  File "/home/airflow/.local/lib/python3.7/site-packages/kaggle/api/kaggle_api_extended.py", line 166, in authenticate
    self.config_file, self.config_dir))
OSError: Could not find kaggle.json. Make sure it's located in /home/***/.kaggle. Or use the environment method.
[2022-06-21 16:37:27,090] {taskinstance.py:1400} INFO - Marking task as FAILED. dag_id=data_ingestion_gcs_dag, task_id=download_dataset_task, execution_date=20220621T163222, start_date=20220621T163726, end_date=20220621T163727
[2022-06-21 16:37:27,099] {standard_task_runner.py:97} ERROR - Failed to execute job 41 for task download_dataset_task (Could not find kaggle.json. Make sure it's located in /home/***/.kaggle. Or use the environment method.; 349)
[2022-06-21 16:37:27,137] {local_task_job.py:156} INFO - Task exited with return code 1
[2022-06-21 16:37:27,176] {local_task_job.py:273} INFO - 0 downstream tasks scheduled from follow-on schedule check
