[2022-06-28 15:06:09,231] {taskinstance.py:1159} INFO - Dependencies all met for <TaskInstance: process-food-waste-data.process_data_task manual__2022-06-28T15:06:03.874231+00:00 [queued]>
[2022-06-28 15:06:09,238] {taskinstance.py:1159} INFO - Dependencies all met for <TaskInstance: process-food-waste-data.process_data_task manual__2022-06-28T15:06:03.874231+00:00 [queued]>
[2022-06-28 15:06:09,238] {taskinstance.py:1356} INFO - 
--------------------------------------------------------------------------------
[2022-06-28 15:06:09,238] {taskinstance.py:1357} INFO - Starting attempt 1 of 2
[2022-06-28 15:06:09,238] {taskinstance.py:1358} INFO - 
--------------------------------------------------------------------------------
[2022-06-28 15:06:09,247] {taskinstance.py:1377} INFO - Executing <Task(PythonOperator): process_data_task> on 2022-06-28 15:06:03.874231+00:00
[2022-06-28 15:06:09,253] {clientserver.py:543} INFO - Closing down clientserver connection
[2022-06-28 15:06:09,253] {standard_task_runner.py:52} INFO - Started process 310 to run task
[2022-06-28 15:06:09,255] {standard_task_runner.py:79} INFO - Running: ['***', 'tasks', 'run', 'process-food-waste-data', 'process_data_task', 'manual__2022-06-28T15:06:03.874231+00:00', '--job-id', '527', '--raw', '--subdir', 'DAGS_FOLDER/02_data_process_dag.py', '--cfg-path', '/tmp/tmpvwvx9eft', '--error-file', '/tmp/tmpogaye_kj']
[2022-06-28 15:06:09,256] {standard_task_runner.py:80} INFO - Job 527: Subtask process_data_task
[2022-06-28 15:06:09,283] {clientserver.py:505} INFO - Error while sending or receiving.
Traceback (most recent call last):
  File "/home/airflow/.local/lib/python3.7/site-packages/py4j/clientserver.py", line 503, in send_command
    self.socket.sendall(command.encode("utf-8"))
ConnectionResetError: [Errno 104] Connection reset by peer
[2022-06-28 15:06:09,283] {clientserver.py:543} INFO - Closing down clientserver connection
[2022-06-28 15:06:09,283] {java_gateway.py:1052} INFO - Exception while sending command.
Traceback (most recent call last):
  File "/home/airflow/.local/lib/python3.7/site-packages/py4j/clientserver.py", line 503, in send_command
    self.socket.sendall(command.encode("utf-8"))
ConnectionResetError: [Errno 104] Connection reset by peer

During handling of the above exception, another exception occurred:

Traceback (most recent call last):
  File "/home/airflow/.local/lib/python3.7/site-packages/py4j/java_gateway.py", line 1038, in send_command
    response = connection.send_command(command)
  File "/home/airflow/.local/lib/python3.7/site-packages/py4j/clientserver.py", line 507, in send_command
    "Error while sending", e, proto.ERROR_ON_SEND)
py4j.protocol.Py4JNetworkError: Error while sending
[2022-06-28 15:06:09,285] {clientserver.py:543} INFO - Closing down clientserver connection
[2022-06-28 15:06:09,290] {task_command.py:370} INFO - Running <TaskInstance: process-food-waste-data.process_data_task manual__2022-06-28T15:06:03.874231+00:00 [running]> on host 375d46b24910
[2022-06-28 15:06:09,335] {taskinstance.py:1571} INFO - Exporting the following env vars:
AIRFLOW_CTX_DAG_OWNER=***
AIRFLOW_CTX_DAG_ID=process-food-waste-data
AIRFLOW_CTX_TASK_ID=process_data_task
AIRFLOW_CTX_EXECUTION_DATE=2022-06-28T15:06:03.874231+00:00
AIRFLOW_CTX_TRY_NUMBER=1
AIRFLOW_CTX_DAG_RUN_ID=manual__2022-06-28T15:06:03.874231+00:00
[2022-06-28 15:06:13,588] {logging_mixin.py:115} INFO - 171  nÂº records
[2022-06-28 15:06:14,608] {logging_mixin.py:115} INFO - There were  8  records eliminated by ensuring date format.
[2022-06-28 15:06:19,006] {taskinstance.py:1889} ERROR - Task failed with exception
Traceback (most recent call last):
  File "/home/airflow/.local/lib/python3.7/site-packages/airflow/operators/python.py", line 171, in execute
    return_value = self.execute_callable()
  File "/home/airflow/.local/lib/python3.7/site-packages/airflow/operators/python.py", line 189, in execute_callable
    return self.python_callable(*self.op_args, **self.op_kwargs)
  File "/opt/airflow/dags/scripts/process_food_waste_data.py", line 89, in process_food_waste_data
    df.write.parquet(f"gs://{BUCKET}/{processed_folder}/food_waste")\
AttributeError: 'NoneType' object has no attribute 'option'
[2022-06-28 15:06:19,018] {taskinstance.py:1400} INFO - Marking task as UP_FOR_RETRY. dag_id=process-food-waste-data, task_id=process_data_task, execution_date=20220628T150603, start_date=20220628T150609, end_date=20220628T150619
[2022-06-28 15:06:19,039] {standard_task_runner.py:97} ERROR - Failed to execute job 527 for task process_data_task ('NoneType' object has no attribute 'option'; 310)
[2022-06-28 15:06:19,062] {local_task_job.py:156} INFO - Task exited with return code 1
[2022-06-28 15:06:19,119] {local_task_job.py:273} INFO - 0 downstream tasks scheduled from follow-on schedule check
