[2022-06-21 14:52:59,924] {taskinstance.py:1159} INFO - Dependencies all met for <TaskInstance: data_ingestion_gcs_dag.download_dataset_task manual__2022-06-21T14:47:46.866256+00:00 [queued]>
[2022-06-21 14:52:59,929] {taskinstance.py:1159} INFO - Dependencies all met for <TaskInstance: data_ingestion_gcs_dag.download_dataset_task manual__2022-06-21T14:47:46.866256+00:00 [queued]>
[2022-06-21 14:52:59,929] {taskinstance.py:1356} INFO - 
--------------------------------------------------------------------------------
[2022-06-21 14:52:59,929] {taskinstance.py:1357} INFO - Starting attempt 1 of 2
[2022-06-21 14:52:59,929] {taskinstance.py:1358} INFO - 
--------------------------------------------------------------------------------
[2022-06-21 14:52:59,940] {taskinstance.py:1377} INFO - Executing <Task(PythonOperator): download_dataset_task> on 2022-06-21 14:47:46.866256+00:00
[2022-06-21 14:52:59,945] {standard_task_runner.py:52} INFO - Started process 354 to run task
[2022-06-21 14:52:59,947] {standard_task_runner.py:79} INFO - Running: ['***', 'tasks', 'run', 'data_ingestion_gcs_dag', 'download_dataset_task', 'manual__2022-06-21T14:47:46.866256+00:00', '--job-id', '7', '--raw', '--subdir', 'DAGS_FOLDER/dags.py', '--cfg-path', '/tmp/tmpnl69ibt3', '--error-file', '/tmp/tmpzbphcg5f']
[2022-06-21 14:52:59,948] {standard_task_runner.py:80} INFO - Job 7: Subtask download_dataset_task
[2022-06-21 14:52:59,982] {task_command.py:370} INFO - Running <TaskInstance: data_ingestion_gcs_dag.download_dataset_task manual__2022-06-21T14:47:46.866256+00:00 [running]> on host 247b3af9617b
[2022-06-21 14:53:00,027] {taskinstance.py:1571} INFO - Exporting the following env vars:
AIRFLOW_CTX_DAG_OWNER=***
AIRFLOW_CTX_DAG_ID=data_ingestion_gcs_dag
AIRFLOW_CTX_TASK_ID=download_dataset_task
AIRFLOW_CTX_EXECUTION_DATE=2022-06-21T14:47:46.866256+00:00
AIRFLOW_CTX_TRY_NUMBER=1
AIRFLOW_CTX_DAG_RUN_ID=manual__2022-06-21T14:47:46.866256+00:00
[2022-06-21 14:53:00,028] {taskinstance.py:1889} ERROR - Task failed with exception
Traceback (most recent call last):
  File "/home/airflow/.local/lib/python3.7/site-packages/airflow/operators/python.py", line 171, in execute
    return_value = self.execute_callable()
  File "/home/airflow/.local/lib/python3.7/site-packages/airflow/operators/python.py", line 189, in execute_callable
    return self.python_callable(*self.op_args, **self.op_kwargs)
  File "/opt/airflow/dags/dags.py", line 25, in download_data
    import opendatasets as op
ModuleNotFoundError: No module named 'opendatasets'
[2022-06-21 14:53:00,034] {taskinstance.py:1400} INFO - Marking task as UP_FOR_RETRY. dag_id=data_ingestion_gcs_dag, task_id=download_dataset_task, execution_date=20220621T144746, start_date=20220621T145259, end_date=20220621T145300
[2022-06-21 14:53:00,042] {standard_task_runner.py:97} ERROR - Failed to execute job 7 for task download_dataset_task (No module named 'opendatasets'; 354)
[2022-06-21 14:53:00,079] {local_task_job.py:156} INFO - Task exited with return code 1
[2022-06-21 14:53:00,106] {local_task_job.py:273} INFO - 0 downstream tasks scheduled from follow-on schedule check
