[2022-06-27 10:52:53,908] {taskinstance.py:1159} INFO - Dependencies all met for <TaskInstance: process-food-waste-data.process_data_task manual__2022-06-27T10:52:48.767832+00:00 [queued]>
[2022-06-27 10:52:53,917] {taskinstance.py:1159} INFO - Dependencies all met for <TaskInstance: process-food-waste-data.process_data_task manual__2022-06-27T10:52:48.767832+00:00 [queued]>
[2022-06-27 10:52:53,917] {taskinstance.py:1356} INFO - 
--------------------------------------------------------------------------------
[2022-06-27 10:52:53,917] {taskinstance.py:1357} INFO - Starting attempt 1 of 2
[2022-06-27 10:52:53,917] {taskinstance.py:1358} INFO - 
--------------------------------------------------------------------------------
[2022-06-27 10:52:53,932] {taskinstance.py:1377} INFO - Executing <Task(PythonOperator): process_data_task> on 2022-06-27 10:52:48.767832+00:00
[2022-06-27 10:52:53,939] {clientserver.py:543} INFO - Closing down clientserver connection
[2022-06-27 10:52:53,939] {standard_task_runner.py:52} INFO - Started process 457 to run task
[2022-06-27 10:52:53,941] {standard_task_runner.py:79} INFO - Running: ['***', 'tasks', 'run', 'process-food-waste-data', 'process_data_task', 'manual__2022-06-27T10:52:48.767832+00:00', '--job-id', '364', '--raw', '--subdir', 'DAGS_FOLDER/02_data_process_dag.py', '--cfg-path', '/tmp/tmpltvg5ris', '--error-file', '/tmp/tmp20dczchy']
[2022-06-27 10:52:53,942] {standard_task_runner.py:80} INFO - Job 364: Subtask process_data_task
[2022-06-27 10:52:53,981] {task_command.py:370} INFO - Running <TaskInstance: process-food-waste-data.process_data_task manual__2022-06-27T10:52:48.767832+00:00 [running]> on host 499e272a57d6
[2022-06-27 10:52:54,043] {taskinstance.py:1571} INFO - Exporting the following env vars:
AIRFLOW_CTX_DAG_OWNER=***
AIRFLOW_CTX_DAG_ID=process-food-waste-data
AIRFLOW_CTX_TASK_ID=process_data_task
AIRFLOW_CTX_EXECUTION_DATE=2022-06-27T10:52:48.767832+00:00
AIRFLOW_CTX_TRY_NUMBER=1
AIRFLOW_CTX_DAG_RUN_ID=manual__2022-06-27T10:52:48.767832+00:00
[2022-06-27 10:52:54,043] {logging_mixin.py:115} INFO - ENTERED FUNCTION
[2022-06-27 10:52:54,045] {logging_mixin.py:115} INFO - gs://dtc-project-data_dtc-project-ritaafranco/raw/brooklyn.parquet
[2022-06-27 10:52:54,674] {clientserver.py:505} INFO - Error while sending or receiving.
Traceback (most recent call last):
  File "/home/airflow/.local/lib/python3.7/site-packages/py4j/clientserver.py", line 503, in send_command
    self.socket.sendall(command.encode("utf-8"))
ConnectionResetError: [Errno 104] Connection reset by peer
[2022-06-27 10:52:54,674] {clientserver.py:543} INFO - Closing down clientserver connection
[2022-06-27 10:52:54,674] {java_gateway.py:1052} INFO - Exception while sending command.
Traceback (most recent call last):
  File "/home/airflow/.local/lib/python3.7/site-packages/py4j/clientserver.py", line 503, in send_command
    self.socket.sendall(command.encode("utf-8"))
ConnectionResetError: [Errno 104] Connection reset by peer

During handling of the above exception, another exception occurred:

Traceback (most recent call last):
  File "/home/airflow/.local/lib/python3.7/site-packages/py4j/java_gateway.py", line 1038, in send_command
    response = connection.send_command(command)
  File "/home/airflow/.local/lib/python3.7/site-packages/py4j/clientserver.py", line 507, in send_command
    "Error while sending", e, proto.ERROR_ON_SEND)
py4j.protocol.Py4JNetworkError: Error while sending
[2022-06-27 10:52:54,676] {clientserver.py:543} INFO - Closing down clientserver connection
[2022-06-27 10:52:58,402] {taskinstance.py:1889} ERROR - Task failed with exception
Traceback (most recent call last):
  File "/home/airflow/.local/lib/python3.7/site-packages/airflow/operators/python.py", line 171, in execute
    return_value = self.execute_callable()
  File "/home/airflow/.local/lib/python3.7/site-packages/airflow/operators/python.py", line 189, in execute_callable
    return self.python_callable(*self.op_args, **self.op_kwargs)
  File "/opt/airflow/dags/scripts/process_food_waste_data.py", line 96, in process_food_waste_data
    print(df.shape)
  File "/opt/airflow/spark/spark-3.2.1-bin-hadoop3.2/python/pyspark/sql/dataframe.py", line 1660, in __getattr__
    "'%s' object has no attribute '%s'" % (self.__class__.__name__, name))
AttributeError: 'DataFrame' object has no attribute 'shape'
[2022-06-27 10:52:58,442] {taskinstance.py:1400} INFO - Marking task as UP_FOR_RETRY. dag_id=process-food-waste-data, task_id=process_data_task, execution_date=20220627T105248, start_date=20220627T105253, end_date=20220627T105258
[2022-06-27 10:52:58,455] {standard_task_runner.py:97} ERROR - Failed to execute job 364 for task process_data_task ('DataFrame' object has no attribute 'shape'; 457)
[2022-06-27 10:52:58,497] {local_task_job.py:156} INFO - Task exited with return code 1
[2022-06-27 10:52:58,526] {local_task_job.py:273} INFO - 0 downstream tasks scheduled from follow-on schedule check
