[2022-06-23 14:24:08,454] {taskinstance.py:1159} INFO - Dependencies all met for <TaskInstance: data_ingestion_to_gcs.trigger scheduled__2020-01-01T00:00:00+00:00 [queued]>
[2022-06-23 14:24:08,464] {taskinstance.py:1159} INFO - Dependencies all met for <TaskInstance: data_ingestion_to_gcs.trigger scheduled__2020-01-01T00:00:00+00:00 [queued]>
[2022-06-23 14:24:08,464] {taskinstance.py:1356} INFO - 
--------------------------------------------------------------------------------
[2022-06-23 14:24:08,464] {taskinstance.py:1357} INFO - Starting attempt 2 of 2
[2022-06-23 14:24:08,465] {taskinstance.py:1358} INFO - 
--------------------------------------------------------------------------------
[2022-06-23 14:24:08,479] {taskinstance.py:1377} INFO - Executing <Task(TriggerDagRunOperator): trigger> on 2020-01-01 00:00:00+00:00
[2022-06-23 14:24:08,484] {standard_task_runner.py:52} INFO - Started process 66 to run task
[2022-06-23 14:24:08,487] {standard_task_runner.py:79} INFO - Running: ['***', 'tasks', 'run', 'data_ingestion_to_gcs', 'trigger', 'scheduled__2020-01-01T00:00:00+00:00', '--job-id', '197', '--raw', '--subdir', 'DAGS_FOLDER/01_data_ingestion_to_gcs.py', '--cfg-path', '/tmp/tmppt90w9os', '--error-file', '/tmp/tmpmd_zrrvp']
[2022-06-23 14:24:08,487] {standard_task_runner.py:80} INFO - Job 197: Subtask trigger
[2022-06-23 14:24:08,530] {task_command.py:370} INFO - Running <TaskInstance: data_ingestion_to_gcs.trigger scheduled__2020-01-01T00:00:00+00:00 [running]> on host 1b414ea15b81
[2022-06-23 14:24:08,596] {taskinstance.py:1571} INFO - Exporting the following env vars:
AIRFLOW_CTX_DAG_OWNER=***
AIRFLOW_CTX_DAG_ID=data_ingestion_to_gcs
AIRFLOW_CTX_TASK_ID=trigger
AIRFLOW_CTX_EXECUTION_DATE=2020-01-01T00:00:00+00:00
AIRFLOW_CTX_TRY_NUMBER=2
AIRFLOW_CTX_DAG_RUN_ID=scheduled__2020-01-01T00:00:00+00:00
[2022-06-23 14:24:08,617] {trigger_dagrun.py:152} INFO - Clearing process-food-waste-data on 2020-01-01T00:00:00+00:00
[2022-06-23 14:24:08,660] {taskinstance.py:1889} ERROR - Task failed with exception
Traceback (most recent call last):
  File "/home/airflow/.local/lib/python3.7/site-packages/airflow/operators/trigger_dagrun.py", line 147, in execute
    replace_microseconds=False,
  File "/home/airflow/.local/lib/python3.7/site-packages/airflow/api/common/trigger_dag.py", line 129, in trigger_dag
    replace_microseconds=replace_microseconds,
  File "/home/airflow/.local/lib/python3.7/site-packages/airflow/api/common/trigger_dag.py", line 76, in _trigger_dag
    f"A Dag Run already exists for dag id {dag_id} at {execution_date} with run id {run_id}"
airflow.exceptions.DagRunAlreadyExists: A Dag Run already exists for dag id process-food-waste-data at 2020-01-01T00:00:00+00:00 with run id manual__2020-01-01T00:00:00+00:00

During handling of the above exception, another exception occurred:

Traceback (most recent call last):
  File "/home/airflow/.local/lib/python3.7/site-packages/airflow/operators/trigger_dagrun.py", line 163, in execute
    dag_run = DagRun.find(dag_id=dag.dag_id, run_id=run_id)[0]
IndexError: list index out of range
[2022-06-23 14:24:08,667] {taskinstance.py:1400} INFO - Marking task as FAILED. dag_id=data_ingestion_to_gcs, task_id=trigger, execution_date=20200101T000000, start_date=20220623T142408, end_date=20220623T142408
[2022-06-23 14:24:08,677] {standard_task_runner.py:97} ERROR - Failed to execute job 197 for task trigger (list index out of range; 66)
[2022-06-23 14:24:08,699] {local_task_job.py:156} INFO - Task exited with return code 1
[2022-06-23 14:24:08,740] {local_task_job.py:273} INFO - 0 downstream tasks scheduled from follow-on schedule check
