[2022-06-27 10:39:51,022] {taskinstance.py:1159} INFO - Dependencies all met for <TaskInstance: process-food-waste-data.process_data_task manual__2022-06-27T10:39:41.681890+00:00 [queued]>
[2022-06-27 10:39:51,034] {taskinstance.py:1159} INFO - Dependencies all met for <TaskInstance: process-food-waste-data.process_data_task manual__2022-06-27T10:39:41.681890+00:00 [queued]>
[2022-06-27 10:39:51,035] {taskinstance.py:1356} INFO - 
--------------------------------------------------------------------------------
[2022-06-27 10:39:51,035] {taskinstance.py:1357} INFO - Starting attempt 1 of 2
[2022-06-27 10:39:51,035] {taskinstance.py:1358} INFO - 
--------------------------------------------------------------------------------
[2022-06-27 10:39:51,056] {taskinstance.py:1377} INFO - Executing <Task(PythonOperator): process_data_task> on 2022-06-27 10:39:41.681890+00:00
[2022-06-27 10:39:51,063] {clientserver.py:543} INFO - Closing down clientserver connection
[2022-06-27 10:39:51,063] {standard_task_runner.py:52} INFO - Started process 278 to run task
[2022-06-27 10:39:51,068] {standard_task_runner.py:79} INFO - Running: ['***', 'tasks', 'run', 'process-food-waste-data', 'process_data_task', 'manual__2022-06-27T10:39:41.681890+00:00', '--job-id', '355', '--raw', '--subdir', 'DAGS_FOLDER/02_data_process_dag.py', '--cfg-path', '/tmp/tmpgt1e43ga', '--error-file', '/tmp/tmp5tkyaz58']
[2022-06-27 10:39:51,069] {standard_task_runner.py:80} INFO - Job 355: Subtask process_data_task
[2022-06-27 10:39:51,132] {task_command.py:370} INFO - Running <TaskInstance: process-food-waste-data.process_data_task manual__2022-06-27T10:39:41.681890+00:00 [running]> on host 43c7a9db556a
[2022-06-27 10:39:51,236] {taskinstance.py:1571} INFO - Exporting the following env vars:
AIRFLOW_CTX_DAG_OWNER=***
AIRFLOW_CTX_DAG_ID=process-food-waste-data
AIRFLOW_CTX_TASK_ID=process_data_task
AIRFLOW_CTX_EXECUTION_DATE=2022-06-27T10:39:41.681890+00:00
AIRFLOW_CTX_TRY_NUMBER=1
AIRFLOW_CTX_DAG_RUN_ID=manual__2022-06-27T10:39:41.681890+00:00
[2022-06-27 10:39:51,237] {logging_mixin.py:115} INFO - ENTERED FUNCTION
[2022-06-27 10:39:51,239] {logging_mixin.py:115} INFO - gs://dtc-project-data_dtc-project-ritaafranco/raw/brooklyn.parquet
[2022-06-27 10:39:51,800] {clientserver.py:505} INFO - Error while sending or receiving.
Traceback (most recent call last):
  File "/home/airflow/.local/lib/python3.7/site-packages/py4j/clientserver.py", line 503, in send_command
    self.socket.sendall(command.encode("utf-8"))
ConnectionResetError: [Errno 104] Connection reset by peer
[2022-06-27 10:39:51,801] {clientserver.py:543} INFO - Closing down clientserver connection
[2022-06-27 10:39:51,801] {java_gateway.py:1052} INFO - Exception while sending command.
Traceback (most recent call last):
  File "/home/airflow/.local/lib/python3.7/site-packages/py4j/clientserver.py", line 503, in send_command
    self.socket.sendall(command.encode("utf-8"))
ConnectionResetError: [Errno 104] Connection reset by peer

During handling of the above exception, another exception occurred:

Traceback (most recent call last):
  File "/home/airflow/.local/lib/python3.7/site-packages/py4j/java_gateway.py", line 1038, in send_command
    response = connection.send_command(command)
  File "/home/airflow/.local/lib/python3.7/site-packages/py4j/clientserver.py", line 507, in send_command
    "Error while sending", e, proto.ERROR_ON_SEND)
py4j.protocol.Py4JNetworkError: Error while sending
[2022-06-27 10:39:51,817] {clientserver.py:543} INFO - Closing down clientserver connection
[2022-06-27 10:40:00,471] {logging_mixin.py:115} INFO - Row(id='5e31d5503b85a2e63d634187', date_collected=datetime.date(2020, 1, 27), retailer_type='counter service', retailer_detail='ready-to-eat and prepackaged health food', food_type='ready-to-eat', food_detail='organic oatmeal', label_type='sticker', label_language='use by', label_date='2020-01-28', approximate_dollar_value=5.25, image_id='IMG_1872', collection_lat=40.69453, collection_long=-73.99447, label_explanation='')
[2022-06-27 10:40:00,472] {python.py:173} INFO - Done. Returned value was: None
[2022-06-27 10:40:00,491] {taskinstance.py:1400} INFO - Marking task as SUCCESS. dag_id=process-food-waste-data, task_id=process_data_task, execution_date=20220627T103941, start_date=20220627T103951, end_date=20220627T104000
[2022-06-27 10:40:00,524] {local_task_job.py:156} INFO - Task exited with return code 0
[2022-06-27 10:40:00,560] {local_task_job.py:273} INFO - 0 downstream tasks scheduled from follow-on schedule check
