[2022-06-28 16:10:03,251] {taskinstance.py:1159} INFO - Dependencies all met for <TaskInstance: data_to_dw_bq.delete_processed_data manual__2022-06-28T16:04:04.878422+00:00 [queued]>
[2022-06-28 16:10:03,258] {taskinstance.py:1159} INFO - Dependencies all met for <TaskInstance: data_to_dw_bq.delete_processed_data manual__2022-06-28T16:04:04.878422+00:00 [queued]>
[2022-06-28 16:10:03,259] {taskinstance.py:1356} INFO - 
--------------------------------------------------------------------------------
[2022-06-28 16:10:03,259] {taskinstance.py:1357} INFO - Starting attempt 2 of 2
[2022-06-28 16:10:03,259] {taskinstance.py:1358} INFO - 
--------------------------------------------------------------------------------
[2022-06-28 16:10:03,272] {taskinstance.py:1377} INFO - Executing <Task(BashOperator): delete_processed_data> on 2022-06-28 16:04:04.878422+00:00
[2022-06-28 16:10:03,279] {clientserver.py:543} INFO - Closing down clientserver connection
[2022-06-28 16:10:03,279] {standard_task_runner.py:52} INFO - Started process 1069 to run task
[2022-06-28 16:10:03,282] {standard_task_runner.py:79} INFO - Running: ['***', 'tasks', 'run', 'data_to_dw_bq', 'delete_processed_data', 'manual__2022-06-28T16:04:04.878422+00:00', '--job-id', '555', '--raw', '--subdir', 'DAGS_FOLDER/03_data to_dw_dag.py', '--cfg-path', '/tmp/tmppo5udtbr', '--error-file', '/tmp/tmpuzj3s_t_']
[2022-06-28 16:10:03,282] {standard_task_runner.py:80} INFO - Job 555: Subtask delete_processed_data
[2022-06-28 16:10:03,321] {task_command.py:370} INFO - Running <TaskInstance: data_to_dw_bq.delete_processed_data manual__2022-06-28T16:04:04.878422+00:00 [running]> on host 7f4c2b65af9b
[2022-06-28 16:10:03,376] {taskinstance.py:1571} INFO - Exporting the following env vars:
AIRFLOW_CTX_DAG_OWNER=***
AIRFLOW_CTX_DAG_ID=data_to_dw_bq
AIRFLOW_CTX_TASK_ID=delete_processed_data
AIRFLOW_CTX_EXECUTION_DATE=2022-06-28T16:04:04.878422+00:00
AIRFLOW_CTX_TRY_NUMBER=2
AIRFLOW_CTX_DAG_RUN_ID=manual__2022-06-28T16:04:04.878422+00:00
[2022-06-28 16:10:03,377] {subprocess.py:62} INFO - Tmp dir root location: 
 /tmp
[2022-06-28 16:10:03,377] {subprocess.py:74} INFO - Running command: ['bash', '-c', 'gsutil rm -r gs://dtc-project-data_dtc-project-ritaafranco/processed/food_waste/*']
[2022-06-28 16:10:03,391] {subprocess.py:85} INFO - Output:
[2022-06-28 16:10:03,648] {clientserver.py:505} INFO - Error while sending or receiving.
Traceback (most recent call last):
  File "/home/airflow/.local/lib/python3.7/site-packages/py4j/clientserver.py", line 503, in send_command
    self.socket.sendall(command.encode("utf-8"))
ConnectionResetError: [Errno 104] Connection reset by peer
[2022-06-28 16:10:03,648] {clientserver.py:543} INFO - Closing down clientserver connection
[2022-06-28 16:10:03,648] {java_gateway.py:1052} INFO - Exception while sending command.
Traceback (most recent call last):
  File "/home/airflow/.local/lib/python3.7/site-packages/py4j/clientserver.py", line 503, in send_command
    self.socket.sendall(command.encode("utf-8"))
ConnectionResetError: [Errno 104] Connection reset by peer

During handling of the above exception, another exception occurred:

Traceback (most recent call last):
  File "/home/airflow/.local/lib/python3.7/site-packages/py4j/java_gateway.py", line 1038, in send_command
    response = connection.send_command(command)
  File "/home/airflow/.local/lib/python3.7/site-packages/py4j/clientserver.py", line 507, in send_command
    "Error while sending", e, proto.ERROR_ON_SEND)
py4j.protocol.Py4JNetworkError: Error while sending
[2022-06-28 16:10:03,650] {clientserver.py:543} INFO - Closing down clientserver connection
[2022-06-28 16:10:05,455] {subprocess.py:92} INFO - ServiceException: 401 Anonymous caller does not have storage.objects.list access to the Google Cloud Storage bucket.
[2022-06-28 16:10:05,615] {subprocess.py:96} INFO - Command exited with return code 1
[2022-06-28 16:10:05,624] {taskinstance.py:1889} ERROR - Task failed with exception
Traceback (most recent call last):
  File "/home/airflow/.local/lib/python3.7/site-packages/airflow/operators/bash.py", line 195, in execute
    f'Bash command failed. The command returned a non-zero exit code {result.exit_code}.'
airflow.exceptions.AirflowException: Bash command failed. The command returned a non-zero exit code 1.
[2022-06-28 16:10:05,627] {taskinstance.py:1400} INFO - Marking task as FAILED. dag_id=data_to_dw_bq, task_id=delete_processed_data, execution_date=20220628T160404, start_date=20220628T161003, end_date=20220628T161005
[2022-06-28 16:10:05,636] {standard_task_runner.py:97} ERROR - Failed to execute job 555 for task delete_processed_data (Bash command failed. The command returned a non-zero exit code 1.; 1069)
[2022-06-28 16:10:05,658] {local_task_job.py:156} INFO - Task exited with return code 1
[2022-06-28 16:10:05,685] {local_task_job.py:273} INFO - 0 downstream tasks scheduled from follow-on schedule check
