[2022-06-22 11:28:43,495] {taskinstance.py:1159} INFO - Dependencies all met for <TaskInstance: data_ingestion_gcs_dag.local_to_gcs_task scheduled__2020-01-01T00:00:00+00:00 [queued]>
[2022-06-22 11:28:43,501] {taskinstance.py:1159} INFO - Dependencies all met for <TaskInstance: data_ingestion_gcs_dag.local_to_gcs_task scheduled__2020-01-01T00:00:00+00:00 [queued]>
[2022-06-22 11:28:43,501] {taskinstance.py:1356} INFO - 
--------------------------------------------------------------------------------
[2022-06-22 11:28:43,501] {taskinstance.py:1357} INFO - Starting attempt 2 of 2
[2022-06-22 11:28:43,501] {taskinstance.py:1358} INFO - 
--------------------------------------------------------------------------------
[2022-06-22 11:28:43,515] {taskinstance.py:1377} INFO - Executing <Task(PythonOperator): local_to_gcs_task> on 2020-01-01 00:00:00+00:00
[2022-06-22 11:28:43,520] {standard_task_runner.py:52} INFO - Started process 509 to run task
[2022-06-22 11:28:43,522] {standard_task_runner.py:79} INFO - Running: ['***', 'tasks', 'run', 'data_ingestion_gcs_dag', 'local_to_gcs_task', 'scheduled__2020-01-01T00:00:00+00:00', '--job-id', '116', '--raw', '--subdir', 'DAGS_FOLDER/dags.py', '--cfg-path', '/tmp/tmp6wre2z5w', '--error-file', '/tmp/tmpiut600i8']
[2022-06-22 11:28:43,522] {standard_task_runner.py:80} INFO - Job 116: Subtask local_to_gcs_task
[2022-06-22 11:28:43,554] {task_command.py:370} INFO - Running <TaskInstance: data_ingestion_gcs_dag.local_to_gcs_task scheduled__2020-01-01T00:00:00+00:00 [running]> on host 69b874fb3dd4
[2022-06-22 11:28:43,603] {taskinstance.py:1571} INFO - Exporting the following env vars:
AIRFLOW_CTX_DAG_OWNER=***
AIRFLOW_CTX_DAG_ID=data_ingestion_gcs_dag
AIRFLOW_CTX_TASK_ID=local_to_gcs_task
AIRFLOW_CTX_EXECUTION_DATE=2020-01-01T00:00:00+00:00
AIRFLOW_CTX_TRY_NUMBER=2
AIRFLOW_CTX_DAG_RUN_ID=scheduled__2020-01-01T00:00:00+00:00
[2022-06-22 11:28:43,604] {taskinstance.py:1889} ERROR - Task failed with exception
Traceback (most recent call last):
  File "/home/airflow/.local/lib/python3.7/site-packages/airflow/operators/python.py", line 171, in execute
    return_value = self.execute_callable()
  File "/home/airflow/.local/lib/python3.7/site-packages/airflow/operators/python.py", line 189, in execute_callable
    return self.python_callable(*self.op_args, **self.op_kwargs)
  File "/opt/airflow/dags/dags.py", line 60, in upload_to_gcs
    client = storage.Client()
  File "/home/airflow/.local/lib/python3.7/site-packages/google/cloud/storage/client.py", line 128, in __init__
    _http=_http,
  File "/home/airflow/.local/lib/python3.7/site-packages/google/cloud/client/__init__.py", line 320, in __init__
    _ClientProjectMixin.__init__(self, project=project, credentials=credentials)
  File "/home/airflow/.local/lib/python3.7/site-packages/google/cloud/client/__init__.py", line 268, in __init__
    project = self._determine_default(project)
  File "/home/airflow/.local/lib/python3.7/site-packages/google/cloud/client/__init__.py", line 287, in _determine_default
    return _determine_default_project(project)
  File "/home/airflow/.local/lib/python3.7/site-packages/google/cloud/_helpers/__init__.py", line 152, in _determine_default_project
    _, project = google.auth.default()
  File "/home/airflow/.local/lib/python3.7/site-packages/google/auth/_default.py", line 546, in default
    credentials, project_id = checker()
  File "/home/airflow/.local/lib/python3.7/site-packages/google/auth/_default.py", line 539, in <lambda>
    lambda: _get_explicit_environ_credentials(quota_project_id=quota_project_id),
  File "/home/airflow/.local/lib/python3.7/site-packages/google/auth/_default.py", line 219, in _get_explicit_environ_credentials
    os.environ[environment_vars.CREDENTIALS], quota_project_id=quota_project_id
  File "/home/airflow/.local/lib/python3.7/site-packages/google/auth/_default.py", line 118, in load_credentials_from_file
    "File {} was not found.".format(filename)
google.auth.exceptions.DefaultCredentialsError: File /.google/credentials/google_credentials.json was not found.
[2022-06-22 11:28:43,610] {taskinstance.py:1400} INFO - Marking task as FAILED. dag_id=data_ingestion_gcs_dag, task_id=local_to_gcs_task, execution_date=20200101T000000, start_date=20220622T112843, end_date=20220622T112843
[2022-06-22 11:28:43,618] {standard_task_runner.py:97} ERROR - Failed to execute job 116 for task local_to_gcs_task (File /.google/credentials/google_credentials.json was not found.; 509)
[2022-06-22 11:28:43,654] {local_task_job.py:156} INFO - Task exited with return code 1
[2022-06-22 11:28:43,684] {local_task_job.py:273} INFO - 0 downstream tasks scheduled from follow-on schedule check
[2022-06-22 13:33:38,255] {taskinstance.py:1159} INFO - Dependencies all met for <TaskInstance: data_ingestion_gcs_dag.local_to_gcs_task scheduled__2020-01-01T00:00:00+00:00 [queued]>
[2022-06-22 13:33:38,263] {taskinstance.py:1159} INFO - Dependencies all met for <TaskInstance: data_ingestion_gcs_dag.local_to_gcs_task scheduled__2020-01-01T00:00:00+00:00 [queued]>
[2022-06-22 13:33:38,263] {taskinstance.py:1356} INFO - 
--------------------------------------------------------------------------------
[2022-06-22 13:33:38,263] {taskinstance.py:1357} INFO - Starting attempt 2 of 2
[2022-06-22 13:33:38,263] {taskinstance.py:1358} INFO - 
--------------------------------------------------------------------------------
[2022-06-22 13:33:38,278] {taskinstance.py:1377} INFO - Executing <Task(PythonOperator): local_to_gcs_task> on 2020-01-01 00:00:00+00:00
[2022-06-22 13:33:38,281] {standard_task_runner.py:52} INFO - Started process 89 to run task
[2022-06-22 13:33:38,284] {standard_task_runner.py:79} INFO - Running: ['***', 'tasks', 'run', 'data_ingestion_gcs_dag', 'local_to_gcs_task', 'scheduled__2020-01-01T00:00:00+00:00', '--job-id', '152', '--raw', '--subdir', 'DAGS_FOLDER/dags.py', '--cfg-path', '/tmp/tmpc9puvw8m', '--error-file', '/tmp/tmpj7c5ecbn']
[2022-06-22 13:33:38,285] {standard_task_runner.py:80} INFO - Job 152: Subtask local_to_gcs_task
[2022-06-22 13:33:38,330] {task_command.py:370} INFO - Running <TaskInstance: data_ingestion_gcs_dag.local_to_gcs_task scheduled__2020-01-01T00:00:00+00:00 [running]> on host 1bd671e47a78
[2022-06-22 13:33:38,385] {taskinstance.py:1571} INFO - Exporting the following env vars:
AIRFLOW_CTX_DAG_OWNER=***
AIRFLOW_CTX_DAG_ID=data_ingestion_gcs_dag
AIRFLOW_CTX_TASK_ID=local_to_gcs_task
AIRFLOW_CTX_EXECUTION_DATE=2020-01-01T00:00:00+00:00
AIRFLOW_CTX_TRY_NUMBER=2
AIRFLOW_CTX_DAG_RUN_ID=scheduled__2020-01-01T00:00:00+00:00
[2022-06-22 13:33:38,398] {taskinstance.py:1889} ERROR - Task failed with exception
Traceback (most recent call last):
  File "/home/airflow/.local/lib/python3.7/site-packages/airflow/operators/python.py", line 171, in execute
    return_value = self.execute_callable()
  File "/home/airflow/.local/lib/python3.7/site-packages/airflow/operators/python.py", line 189, in execute_callable
    return self.python_callable(*self.op_args, **self.op_kwargs)
  File "/opt/airflow/dags/dags.py", line 64, in upload_to_gcs
    blob.upload_from_filename(local_file)
  File "/home/airflow/.local/lib/python3.7/site-packages/google/cloud/storage/blob.py", line 2720, in upload_from_filename
    with open(filename, "rb") as file_obj:
FileNotFoundError: [Errno 2] No such file or directory: '/opt/airflow/brooklyn.parquet'
[2022-06-22 13:33:38,404] {taskinstance.py:1400} INFO - Marking task as FAILED. dag_id=data_ingestion_gcs_dag, task_id=local_to_gcs_task, execution_date=20200101T000000, start_date=20220622T133338, end_date=20220622T133338
[2022-06-22 13:33:38,415] {standard_task_runner.py:97} ERROR - Failed to execute job 152 for task local_to_gcs_task ([Errno 2] No such file or directory: '/opt/airflow/brooklyn.parquet'; 89)
[2022-06-22 13:33:38,456] {local_task_job.py:156} INFO - Task exited with return code 1
[2022-06-22 13:33:38,527] {local_task_job.py:273} INFO - 0 downstream tasks scheduled from follow-on schedule check
