[2022-06-28 14:51:56,442] {taskinstance.py:1159} INFO - Dependencies all met for <TaskInstance: process-food-waste-data.process_data_task manual__2022-06-28T14:51:50.432960+00:00 [queued]>
[2022-06-28 14:51:56,448] {taskinstance.py:1159} INFO - Dependencies all met for <TaskInstance: process-food-waste-data.process_data_task manual__2022-06-28T14:51:50.432960+00:00 [queued]>
[2022-06-28 14:51:56,448] {taskinstance.py:1356} INFO - 
--------------------------------------------------------------------------------
[2022-06-28 14:51:56,448] {taskinstance.py:1357} INFO - Starting attempt 1 of 2
[2022-06-28 14:51:56,448] {taskinstance.py:1358} INFO - 
--------------------------------------------------------------------------------
[2022-06-28 14:51:56,457] {taskinstance.py:1377} INFO - Executing <Task(PythonOperator): process_data_task> on 2022-06-28 14:51:50.432960+00:00
[2022-06-28 14:51:56,462] {clientserver.py:543} INFO - Closing down clientserver connection
[2022-06-28 14:51:56,462] {standard_task_runner.py:52} INFO - Started process 310 to run task
[2022-06-28 14:51:56,464] {standard_task_runner.py:79} INFO - Running: ['***', 'tasks', 'run', 'process-food-waste-data', 'process_data_task', 'manual__2022-06-28T14:51:50.432960+00:00', '--job-id', '504', '--raw', '--subdir', 'DAGS_FOLDER/02_data_process_dag.py', '--cfg-path', '/tmp/tmp3qqxgel0', '--error-file', '/tmp/tmp4p7sbk6c']
[2022-06-28 14:51:56,465] {standard_task_runner.py:80} INFO - Job 504: Subtask process_data_task
[2022-06-28 14:51:56,496] {task_command.py:370} INFO - Running <TaskInstance: process-food-waste-data.process_data_task manual__2022-06-28T14:51:50.432960+00:00 [running]> on host 3fcea2aa00ee
[2022-06-28 14:51:56,540] {clientserver.py:505} INFO - Error while sending or receiving.
Traceback (most recent call last):
  File "/home/airflow/.local/lib/python3.7/site-packages/py4j/clientserver.py", line 503, in send_command
    self.socket.sendall(command.encode("utf-8"))
ConnectionResetError: [Errno 104] Connection reset by peer
[2022-06-28 14:51:56,540] {clientserver.py:543} INFO - Closing down clientserver connection
[2022-06-28 14:51:56,541] {java_gateway.py:1052} INFO - Exception while sending command.
Traceback (most recent call last):
  File "/home/airflow/.local/lib/python3.7/site-packages/py4j/clientserver.py", line 503, in send_command
    self.socket.sendall(command.encode("utf-8"))
ConnectionResetError: [Errno 104] Connection reset by peer

During handling of the above exception, another exception occurred:

Traceback (most recent call last):
  File "/home/airflow/.local/lib/python3.7/site-packages/py4j/java_gateway.py", line 1038, in send_command
    response = connection.send_command(command)
  File "/home/airflow/.local/lib/python3.7/site-packages/py4j/clientserver.py", line 507, in send_command
    "Error while sending", e, proto.ERROR_ON_SEND)
py4j.protocol.Py4JNetworkError: Error while sending
[2022-06-28 14:51:56,542] {clientserver.py:543} INFO - Closing down clientserver connection
[2022-06-28 14:51:56,543] {taskinstance.py:1571} INFO - Exporting the following env vars:
AIRFLOW_CTX_DAG_OWNER=***
AIRFLOW_CTX_DAG_ID=process-food-waste-data
AIRFLOW_CTX_TASK_ID=process_data_task
AIRFLOW_CTX_EXECUTION_DATE=2022-06-28T14:51:50.432960+00:00
AIRFLOW_CTX_TRY_NUMBER=1
AIRFLOW_CTX_DAG_RUN_ID=manual__2022-06-28T14:51:50.432960+00:00
[2022-06-28 14:51:56,543] {logging_mixin.py:115} INFO - ENTERED FUNCTION
[2022-06-28 14:52:00,917] {logging_mixin.py:115} INFO - [Row(date_collected=datetime.date(2020, 1, 27), retailer_type='counter service', retailer_detail='ready-to-eat and prepackaged health food', food_type='ready-to-eat', food_detail='organic oatmeal', label_type='sticker', label_language='use by', label_date='2020-01-28', approximate_dollar_value=5.25, collection_lat=40.69453, collection_long=-73.99447, label_explanation='')]
[2022-06-28 14:52:01,890] {logging_mixin.py:115} INFO - 171  nÂº records
[2022-06-28 14:52:02,731] {logging_mixin.py:115} INFO - There were  8  records eliminated by ensuring date format.
[2022-06-28 14:52:03,292] {logging_mixin.py:115} INFO - [Row(date_collected=datetime.date(2020, 1, 27), retailer_type='counter service', retailer_detail='ready-to-eat and prepackaged health food', food_type='ready-to-eat', food_detail='organic oatmeal', label_type='sticker', label_language='use by', label_date=datetime.date(2020, 1, 28), approximate_dollar_value=5.25, collection_lat=40.69453, collection_long=-73.99447, label_explanation='', no_days_untill_expire=-1)]
[2022-06-28 14:52:03,298] {logging_mixin.py:115} INFO - df normal schema StructType(List(StructField(date_collected,DateType,true),StructField(retailer_type,StringType,true),StructField(retailer_detail,StringType,true),StructField(food_type,StringType,true),StructField(food_detail,StringType,true),StructField(label_type,StringType,true),StructField(label_language,StringType,true),StructField(label_date,DateType,true),StructField(approximate_dollar_value,DoubleType,true),StructField(collection_lat,DoubleType,true),StructField(collection_long,DoubleType,true),StructField(label_explanation,StringType,true),StructField(no_days_untill_expire,IntegerType,true)))
[2022-06-28 14:52:03,298] {taskinstance.py:1889} ERROR - Task failed with exception
Traceback (most recent call last):
  File "/home/airflow/.local/lib/python3.7/site-packages/airflow/operators/python.py", line 171, in execute
    return_value = self.execute_callable()
  File "/home/airflow/.local/lib/python3.7/site-packages/airflow/operators/python.py", line 189, in execute_callable
    return self.python_callable(*self.op_args, **self.op_kwargs)
  File "/opt/airflow/dags/scripts/process_food_waste_data.py", line 95, in process_food_waste_data
    df_schema = spark.CreateDataFrame(df, food_waste_schema)
AttributeError: 'SparkSession' object has no attribute 'CreateDataFrame'
[2022-06-28 14:52:03,305] {taskinstance.py:1400} INFO - Marking task as UP_FOR_RETRY. dag_id=process-food-waste-data, task_id=process_data_task, execution_date=20220628T145150, start_date=20220628T145156, end_date=20220628T145203
[2022-06-28 14:52:03,318] {standard_task_runner.py:97} ERROR - Failed to execute job 504 for task process_data_task ('SparkSession' object has no attribute 'CreateDataFrame'; 310)
[2022-06-28 14:52:03,329] {local_task_job.py:156} INFO - Task exited with return code 1
[2022-06-28 14:52:03,361] {local_task_job.py:273} INFO - 0 downstream tasks scheduled from follow-on schedule check
