[2022-06-27 10:24:39,965] {taskinstance.py:1159} INFO - Dependencies all met for <TaskInstance: process-food-waste-data.process_data_task manual__2022-06-27T10:23:31.765589+00:00 [queued]>
[2022-06-27 10:24:39,975] {taskinstance.py:1159} INFO - Dependencies all met for <TaskInstance: process-food-waste-data.process_data_task manual__2022-06-27T10:23:31.765589+00:00 [queued]>
[2022-06-27 10:24:39,976] {taskinstance.py:1356} INFO - 
--------------------------------------------------------------------------------
[2022-06-27 10:24:39,976] {taskinstance.py:1357} INFO - Starting attempt 1 of 2
[2022-06-27 10:24:39,976] {taskinstance.py:1358} INFO - 
--------------------------------------------------------------------------------
[2022-06-27 10:24:39,990] {taskinstance.py:1377} INFO - Executing <Task(PythonOperator): process_data_task> on 2022-06-27 10:23:31.765589+00:00
[2022-06-27 10:24:39,997] {clientserver.py:543} INFO - Closing down clientserver connection
[2022-06-27 10:24:39,997] {standard_task_runner.py:52} INFO - Started process 331 to run task
[2022-06-27 10:24:40,002] {standard_task_runner.py:79} INFO - Running: ['***', 'tasks', 'run', 'process-food-waste-data', 'process_data_task', 'manual__2022-06-27T10:23:31.765589+00:00', '--job-id', '328', '--raw', '--subdir', 'DAGS_FOLDER/02_data_process_dag.py', '--cfg-path', '/tmp/tmpabiwywxd', '--error-file', '/tmp/tmp81vhsm_b']
[2022-06-27 10:24:40,003] {standard_task_runner.py:80} INFO - Job 328: Subtask process_data_task
[2022-06-27 10:24:40,055] {task_command.py:370} INFO - Running <TaskInstance: process-food-waste-data.process_data_task manual__2022-06-27T10:23:31.765589+00:00 [running]> on host ae7a9033af81
[2022-06-27 10:24:40,130] {taskinstance.py:1571} INFO - Exporting the following env vars:
AIRFLOW_CTX_DAG_OWNER=***
AIRFLOW_CTX_DAG_ID=process-food-waste-data
AIRFLOW_CTX_TASK_ID=process_data_task
AIRFLOW_CTX_EXECUTION_DATE=2022-06-27T10:23:31.765589+00:00
AIRFLOW_CTX_TRY_NUMBER=1
AIRFLOW_CTX_DAG_RUN_ID=manual__2022-06-27T10:23:31.765589+00:00
[2022-06-27 10:24:40,131] {logging_mixin.py:115} INFO - ENTERED FUNCTION
[2022-06-27 10:24:40,399] {clientserver.py:505} INFO - Error while sending or receiving.
Traceback (most recent call last):
  File "/home/airflow/.local/lib/python3.7/site-packages/py4j/clientserver.py", line 503, in send_command
    self.socket.sendall(command.encode("utf-8"))
ConnectionResetError: [Errno 104] Connection reset by peer
[2022-06-27 10:24:40,400] {clientserver.py:543} INFO - Closing down clientserver connection
[2022-06-27 10:24:40,400] {java_gateway.py:1052} INFO - Exception while sending command.
Traceback (most recent call last):
  File "/home/airflow/.local/lib/python3.7/site-packages/py4j/clientserver.py", line 503, in send_command
    self.socket.sendall(command.encode("utf-8"))
ConnectionResetError: [Errno 104] Connection reset by peer

During handling of the above exception, another exception occurred:

Traceback (most recent call last):
  File "/home/airflow/.local/lib/python3.7/site-packages/py4j/java_gateway.py", line 1038, in send_command
    response = connection.send_command(command)
  File "/home/airflow/.local/lib/python3.7/site-packages/py4j/clientserver.py", line 507, in send_command
    "Error while sending", e, proto.ERROR_ON_SEND)
py4j.protocol.Py4JNetworkError: Error while sending
[2022-06-27 10:24:40,404] {clientserver.py:543} INFO - Closing down clientserver connection
[2022-06-27 10:24:47,210] {taskinstance.py:1889} ERROR - Task failed with exception
Traceback (most recent call last):
  File "/home/airflow/.local/lib/python3.7/site-packages/airflow/operators/python.py", line 171, in execute
    return_value = self.execute_callable()
  File "/home/airflow/.local/lib/python3.7/site-packages/airflow/operators/python.py", line 189, in execute_callable
    return self.python_callable(*self.op_args, **self.op_kwargs)
  File "/opt/airflow/dags/scripts/process_food_waste_data.py", line 87, in process_food_waste_data
    print(df.shape)
  File "/opt/airflow/spark/spark-3.2.1-bin-hadoop3.2/python/pyspark/sql/dataframe.py", line 1660, in __getattr__
    "'%s' object has no attribute '%s'" % (self.__class__.__name__, name))
AttributeError: 'DataFrame' object has no attribute 'shape'
[2022-06-27 10:24:47,224] {taskinstance.py:1400} INFO - Marking task as UP_FOR_RETRY. dag_id=process-food-waste-data, task_id=process_data_task, execution_date=20220627T102331, start_date=20220627T102439, end_date=20220627T102447
[2022-06-27 10:24:47,244] {standard_task_runner.py:97} ERROR - Failed to execute job 328 for task process_data_task ('DataFrame' object has no attribute 'shape'; 331)
[2022-06-27 10:24:47,263] {local_task_job.py:156} INFO - Task exited with return code 1
[2022-06-27 10:24:47,294] {local_task_job.py:273} INFO - 0 downstream tasks scheduled from follow-on schedule check
