[2022-06-23 17:55:36,077] {taskinstance.py:1159} INFO - Dependencies all met for <TaskInstance: process-food-waste-data.process_data_task manual__2022-06-23T17:55:30.780482+00:00 [queued]>
[2022-06-23 17:55:36,085] {taskinstance.py:1159} INFO - Dependencies all met for <TaskInstance: process-food-waste-data.process_data_task manual__2022-06-23T17:55:30.780482+00:00 [queued]>
[2022-06-23 17:55:36,085] {taskinstance.py:1356} INFO - 
--------------------------------------------------------------------------------
[2022-06-23 17:55:36,085] {taskinstance.py:1357} INFO - Starting attempt 1 of 2
[2022-06-23 17:55:36,085] {taskinstance.py:1358} INFO - 
--------------------------------------------------------------------------------
[2022-06-23 17:55:36,100] {taskinstance.py:1377} INFO - Executing <Task(PythonOperator): process_data_task> on 2022-06-23 17:55:30.780482+00:00
[2022-06-23 17:55:36,107] {clientserver.py:543} INFO - Closing down clientserver connection
[2022-06-23 17:55:36,106] {standard_task_runner.py:52} INFO - Started process 196 to run task
[2022-06-23 17:55:36,110] {standard_task_runner.py:79} INFO - Running: ['***', 'tasks', 'run', 'process-food-waste-data', 'process_data_task', 'manual__2022-06-23T17:55:30.780482+00:00', '--job-id', '297', '--raw', '--subdir', 'DAGS_FOLDER/02_data_process_dag.py', '--cfg-path', '/tmp/tmplcjwocsh', '--error-file', '/tmp/tmp7p7kty84']
[2022-06-23 17:55:36,110] {standard_task_runner.py:80} INFO - Job 297: Subtask process_data_task
[2022-06-23 17:55:36,152] {task_command.py:370} INFO - Running <TaskInstance: process-food-waste-data.process_data_task manual__2022-06-23T17:55:30.780482+00:00 [running]> on host f744cb059a8c
[2022-06-23 17:55:36,182] {clientserver.py:505} INFO - Error while sending or receiving.
Traceback (most recent call last):
  File "/home/airflow/.local/lib/python3.7/site-packages/py4j/clientserver.py", line 503, in send_command
    self.socket.sendall(command.encode("utf-8"))
ConnectionResetError: [Errno 104] Connection reset by peer
[2022-06-23 17:55:36,182] {clientserver.py:543} INFO - Closing down clientserver connection
[2022-06-23 17:55:36,182] {java_gateway.py:1052} INFO - Exception while sending command.
Traceback (most recent call last):
  File "/home/airflow/.local/lib/python3.7/site-packages/py4j/clientserver.py", line 503, in send_command
    self.socket.sendall(command.encode("utf-8"))
ConnectionResetError: [Errno 104] Connection reset by peer

During handling of the above exception, another exception occurred:

Traceback (most recent call last):
  File "/home/airflow/.local/lib/python3.7/site-packages/py4j/java_gateway.py", line 1038, in send_command
    response = connection.send_command(command)
  File "/home/airflow/.local/lib/python3.7/site-packages/py4j/clientserver.py", line 507, in send_command
    "Error while sending", e, proto.ERROR_ON_SEND)
py4j.protocol.Py4JNetworkError: Error while sending
[2022-06-23 17:55:36,184] {clientserver.py:543} INFO - Closing down clientserver connection
[2022-06-23 17:55:36,228] {taskinstance.py:1571} INFO - Exporting the following env vars:
AIRFLOW_CTX_DAG_OWNER=***
AIRFLOW_CTX_DAG_ID=process-food-waste-data
AIRFLOW_CTX_TASK_ID=process_data_task
AIRFLOW_CTX_EXECUTION_DATE=2022-06-23T17:55:30.780482+00:00
AIRFLOW_CTX_TRY_NUMBER=1
AIRFLOW_CTX_DAG_RUN_ID=manual__2022-06-23T17:55:30.780482+00:00
[2022-06-23 17:55:41,975] {logging_mixin.py:115} INFO - Row(id='5e31d5503b85a2e63d634187', date_collected=datetime.date(2020, 1, 27), retailer_type='counter service', retailer_detail='ready-to-eat and prepackaged health food', food_type='ready-to-eat', food_detail='organic oatmeal', label_type='sticker', label_language='use by', label_date='2020-01-28', approximate_dollar_value=5.25, image_id='IMG_1872', collection_lat=40.69453, collection_long=-73.99447, label_explanation='')
[2022-06-23 17:55:41,976] {python.py:173} INFO - Done. Returned value was: None
[2022-06-23 17:55:41,990] {taskinstance.py:1400} INFO - Marking task as SUCCESS. dag_id=process-food-waste-data, task_id=process_data_task, execution_date=20220623T175530, start_date=20220623T175536, end_date=20220623T175541
[2022-06-23 17:55:42,023] {local_task_job.py:156} INFO - Task exited with return code 0
[2022-06-23 17:55:42,048] {local_task_job.py:273} INFO - 0 downstream tasks scheduled from follow-on schedule check
